Workbook

Sheet 전월말일
A1: 서울탁주 강동연합제조장
A3: 현 황 일 보 | AI3: 46112
B5: 1.주료사입현황
B7: 이월수량 | J7: 당일사입수량 | R7: 계 | Z7: 동상제성수량 | AH7: 당일 잔수량 | AP7: 적요
R9: =B9+J9 -> 0 | AH9: =R9-Z9 -> 0
B12: 2.주류제성 및 출고현황
B14: 이월수량 | I14: 당일제성수량 | Q14: 계 | Y14: 당일판매수량 | AH14: 당일 잔수량 | AP14: 적요
I16: =Z9*4910 -> 0 | Q16: =B16+I16 -> 0 | AH16: =Q16-Y17 -> 0
Y17: =Y16*0.75 -> 0
B19: 3.주류제성 및 출고현황
B21: 익일 보쌈 | E21: 보쌈 | I21: 입국 | M21: 1단 | U21: 2단 1일 | Y21: 2단 2일 | AC21: 3일 이상 | AG21: 4일 이상 | AK21: 5일 이상 | AO21: 6일 이상 | AS21: 계
M22: 1일 | Q22: 2일
AK23: 0 | AO23: 0 | AS23: =SUM(U23:AN26) -> 0
B28: 4.원료 및 연료수불상황
N29: =U23*8 -> 0 | P29: =Y23*3 -> 0 | R29: =AC23*3 -> 0
B30: 구분 | H30: 백미 | N30: 팽화미 | T30: 올리고당 | Z30: 효모 | AF30: 곡자 | AL30: 감미 | AR30: 구연산
B31: 이월수량
B32: 당일구입
B33: 당일사용 | H33: =U23*7 -> 0 | N33: =N29+P29+R29 -> 0 | T33: =AC23*72 -> 0 | Z33: =M23*500 -> 0 | AF33: =U23*4 -> 0 | AL33: =Z9*545 -> 0 | AR33: =Z9*95 -> 0
B34: 잔량 | H34: =H31+H32-H33 -> 0 | N34: =N31+N32-N33 -> 0 | T34: =T31+T32-T33 -> 0 | Z34: =Z31+Z32-Z33 -> 0 | AF34: =AF31+AF32-AF33 -> 0 | AL34: =AL31+AL32-AL33 -> 0 | AR34: =AR31+AR32-AR33 -> 0

Sheet 1일
A1: 서 울 탁 주 강 동 연 합 제 조 장
A3: 현 황 일 보 | AI3: =전월말일!AI3+1 -> 46113
B5: 1.주료사입현황
B6: 이월수량 | J6: 당일사입수량 | R6: 계 | Z6: 당일제성수량 | AH6: 당일 잔수량 | AP6: 적요
B8: =전월말일!AH9 -> 0 | R8: =B8+J8 -> 0 | AH8: =R8-Z8 -> 0 | AY8: =AH8 -> 0
B11: 2.주류제성 및 출고현황
B12: 이월수량 | I12: 당일제성수량 | Q12: 계 | Y12: 당일판매수량 | AH12: 당일 잔수량 | AP12: 적요
B14: =전월말일!AH16 -> 0 | I14: =Z8*4910 -> 0 | Q14: =B14+I14 -> 0 | AH14: =Q14-Y15 -> 0
Y15: =Y14*0.75 -> 0
B17: 3.주류제성 및 출고현황
B18: 익일 보쌈 | E18: 보쌈 | I18: 입국 | M18: 1단 | U18: 2단 1일 | Y18: 2단 2일 | AC18: 3일 이상 | AG18: 4일 이상 | AK18: 5일 이상 | AO18: 6일 이상 | AS18: 계 | AZ18: =AH8-AS20 -> 0
M19: 1일 | Q19: 2일
I20: =전월말일!E23 -> 0 | M20: =전월말일!I23 -> 0 | Q20: =전월말일!Q23+전월말일!M25-J8 -> 0 | U20: =J8 -> 0 | Y20: =전월말일!U23 -> 0 | AC20: =전월말일!Y23 -> 0 | AG20: =AS20-U20-Y20-AC20 -> 0 | AK20: 0 | AO20: 0 | AS20: =AH8 -> 0 | AY20: 1 | AZ20: 2
AY21: 12 | AZ21: 12
I22: =전월말일!E25 -> 0 | M22: =전월말일!I25 -> 0
B25: 4.원료 및 연료수불상황 | O25: =U20*8 -> 0 | P25: =Y20*3 -> 0 | R25: =AC20*3 -> 0
B26: 구분 | H26: 백미 | N26: 팽화미 | T26: 올리고당 | Z26: 효모 | AF26: 곡자 | AL26: 감미 | AR26: 구연산
B27: 이월수량 | H27: =전월말일!H34 -> 0 | N27: =전월말일!N34 -> 0 | T27: =전월말일!T34 -> 0 | Z27: =전월말일!Z34 -> 0 | AF27: =전월말일!AF34 -> 0 | AL27: =전월말일!AL34 -> 0 | AR27: =전월말일!AR34 -> 0
B28: 당일구입
B29: 당일사용 | H29: =J8*280/40 -> 0 | N29: =SUM(N25:S25) -> 0 | T29: =AC20*72 -> 0 | Z29: =M20*500+Z31 -> 0 | AF29: =J8*4 -> 0 | AL29: =Z8*545 -> 0 | AR29: =Z8*95 -> 0
B30: 잔량 | H30: =H27+H28-H29 -> 0 | N30: =N27+N28-N29 -> 0 | T30: =T27+T28-T29 -> 0 | Z30: =Z27+Z28-Z29 -> 0 | AF30: =AF27+AF28-AF29 -> 0 | AL30: =AL27+AL28-AL29 -> 0 | AR30: =AR27+AR28-AR29 -> 0
B33: 6. 용기, 마개
I34: 전일잔량 | P34: 입고 | W34: 출고 | AD34: 파손 | AJ34: 파손재고 | AQ34: 금일재고
B35: 용기 | W35: =Y14 -> 0 | AJ35: =AD35 -> 0 | AQ35: =I35+P35-W35-AD35 -> 0
B36: 마개 | W36: =W35 -> 0 | AJ36: =AD36 -> 0 | AQ36: =I36+P36-W36-AD36 -> 0

Sheet 2일
A1: 서 울 탁 주 강 동 연 합 제 조 장
A3: 현 황 일 보 | AI3: ='1일'!AI3:AW4+1 -> 46114
B5: 1.주료사입현황
B6: 이월수량 | J6: 당일사입수량 | R6: 계 | Z6: 당일제성수량 | AH6: 당일 잔수량 | AP6: 적요
B8: ='1일'!AH8 -> 0 | R8: =B8+J8 -> 0 | AH8: =R8-Z8 -> 0 | AY8: =AH8 -> 0
B11: 2.주류제성 및 출고현황
B12: 이월수량 | I12: 당일제성수량 | Q12: 계 | Y12: 당일판매수량 | AH12: 당일 잔수량 | AP12: 적요
B14: ='1일'!AH14 -> 0 | I14: =Z8*4910 -> 0 | Q14: =B14+I14 -> 0 | AH14: =Q14-Y15 -> 0
Y15: =Y14*0.75 -> 0
B17: 3.주류제성 및 출고현황
B18: 익일 보쌈 | E18: 보쌈 | I18: 입국 | M18: 1단 | U18: 2단 1일 | Y18: 2단 2일 | AC18: 3일 이상 | AG18: 4일 이상 | AK18: 5일 이상 | AO18: 6일 이상 | AS18: 계
M19: 1일 | Q19: 2일
I20: ='1일'!E20 -> 0 | M20: ='1일'!I20 -> 0 | Q20: ='1일'!Q20+'1일'!M22-'2일'!J8 -> 0 | U20: =J8 -> 0 | Y20: ='1일'!U20 -> 0 | AC20: ='1일'!Y20 -> 0 | AG20: =AS20-U20-Y20-AC20 -> 0 | AK20: 0 | AO20: 0 | AS20: =AH8 -> 0
AY21: =AH8-U20-Y20-AC20 -> 0
I22: ='1일'!E22 -> 0 | M22: ='1일'!I22 -> 0 | AY22: =AG20 -> 0
B25: 4.원료 및 연료수불상황 | O25: =U20*8 -> 0 | P25: =Y20*3 -> 0 | R25: =AC20*3 -> 0
B26: 구분 | H26: 백미 | N26: 팽화미 | T26: 올리고당 | Z26: 효모 | AF26: 곡자 | AL26: 감미 | AR26: 구연산
B27: 이월수량 | H27: ='1일'!H30:M30 -> 0 | N27: ='1일'!N30:S30 -> 0 | T27: ='1일'!T30:Y30 -> 0 | Z27: ='1일'!Z30:AE30 -> 0 | AF27: ='1일'!AF30:AK30 -> 0 | AL27: ='1일'!AL30:AQ30 -> 0 | AR27: ='1일'!AR30:AW30 -> 0
B28: 당일구입
B29: 당일사용 | H29: =J8*280/40 -> 0 | N29: =SUM(N25:S25) -> 0 | T29: =AC20*72 -> 0 | Z29: =M20*500 -> 0 | AF29: =J8*4 -> 0 | AL29: =Z8*545 -> 0 | AR29: =Z8*95 -> 0
B30: 잔량 | H30: =H27+H28-H29 -> 0 | N30: =N27+N28-N29 -> 0 | T30: =T27+T28-T29 -> 0 | Z30: =Z27+Z28-Z29 -> 0 | AF30: =AF27+AF28-AF29 -> 0 | AL30: =AL27+AL28-AL29 -> 0 | AR30: =AR27+AR28-AR29 -> 0
B32: 6. 용기, 마개
I33: 전일잔량 | P33: 입고 | W33: 출고 | AD33: 파손 | AJ33: 파손재고 | AQ33: 금일재고
B34: 용기 | I34: ='1일'!AQ35 -> 0 | W34: =Y14 -> 0 | AJ34: =AD34+'1일'!AJ35:AP35 -> 0 | AQ34: =I34+P34-W34-AD34 -> 0
B35: 마개 | I35: ='1일'!AQ36 -> 0 | P35: =T32*672000 -> 0 | W35: =W34 -> 0 | AJ35: =AD35+'1일'!AJ36:AP36 -> 0 | AQ35: =I35+P35-W35-AD35 -> 0
AV36: 22880

Sheet 3일
A1: 서 울 탁 주 강 동 연 합 제 조 장
A3: 현 황 일 보 | AI3: ='2일'!AI3:AW4+1 -> 46115
B5: 1.주료사입현황
B6: 이월수량 | J6: 당일사입수량 | R6: 계 | Z6: 당일제성수량 | AH6: 당일 잔수량 | AP6: 적요
B8: ='2일'!AH8 -> 0 | R8: =B8+J8 -> 0 | AH8: =R8-Z8 -> 0 | AY8: =AH8 -> 0
B11: 2.주류제성 및 출고현황
B12: 이월수량 | I12: 당일제성수량 | Q12: 계 | Y12: 당일판매수량 | AH12: 당일 잔수량 | AP12: 적요
B14: ='2일'!AH14 -> 0 | I14: =Z8*4910 -> 0 | Q14: =B14+I14 -> 0 | AH14: =Q14-Y15 -> 0
Y15: =Y14*0.75 -> 0
B17: 3.주류제성 및 출고현황
B18: 익일 보쌈 | E18: 보쌈 | I18: 입국 | M18: 1단 | U18: 2단 1일 | Y18: 2단 2일 | AC18: 3일 이상 | AG18: 4일 이상 | AK18: 5일 이상 | AO18: 6일 이상 | AS18: 계
M19: 1일 | Q19: 2일
I20: ='2일'!E20 -> 0 | M20: ='2일'!I20 -> 0 | Q20: ='2일'!Q20+'2일'!M22-'3일'!J8 -> 0 | U20: =J8 -> 0 | Y20: ='2일'!U20 -> 0 | AC20: ='2일'!Y20 -> 0 | AG20: =AY21 -> 0 | AK20: 0 | AO20: 0 | AS20: =AH8 -> 0
AY21: =AH8-U20-Y20-AC20 -> 0
I22: ='2일'!E22 -> 0 | M22: ='2일'!I22 -> 0 | AY22: =AG20 -> 0
B25: 4.원료 및 연료수불상황 | O25: =U20*8 -> 0 | P25: =Y20*3 -> 0 | R25: =AC20*3 -> 0
B26: 구분 | H26: 백미 | N26: 팽화미 | T26: 올리고당 | Z26: 효모 | AF26: 곡자 | AL26: 감미 | AR26: 구연산
B27: 이월수량 | H27: ='2일'!H30:M30 -> 0 | N27: ='2일'!N30:S30 -> 0 | T27: ='2일'!T30:Y30 -> 0 | Z27: ='2일'!Z30:AE30 -> 0 | AF27: ='2일'!AF30:AK30 -> 0 | AL27: ='2일'!AL30:AQ30 -> 0 | AR27: ='2일'!AR30:AW30 -> 0
B28: 당일구입
B29: 당일사용 | H29: =J8*280/40 -> 0 | N29: =SUM(N25:S25) -> 0 | T29: =AC20*72 -> 0 | Z29: =M20*500+Z31 -> 0 | AF29: =J8*4 -> 0 | AL29: =Z8*545 -> 0 | AR29: =Z8*95 -> 0
B30: 잔량 | H30: =H27+H28-H29 -> 0 | N30: =N27+N28-N29 -> 0 | T30: =T27+T28-T29 -> 0 | Z30: =Z27+Z28-Z29 -> 0 | AF30: =AF27+AF28-AF29 -> 0 | AL30: =AL27+AL28-AL29 -> 0 | AR30: =AR27+AR28-AR29 -> 0
B33: 6. 용기, 마개 | P33: 2 | T33: 0
I34: 전일잔량 | P34: 입고 | W34: 출고 | AD34: 파손 | AJ34: 파손재고 | AQ34: 금일재고
B35: 용기 | I35: ='2일'!AQ34 -> 0 | W35: =Y14 -> 0 | AJ35: =AD35+'2일'!AJ34:AP34 -> 0 | AQ35: =I35+P35-W35-AD35 -> 0
B36: 마개 | I36: ='2일'!AQ35 -> 0 | P36: =BA36*90000 -> 0 | W36: =W35 -> 0 | AJ36: =AD36+'2일'!AJ35:AP35 -> 0 | AQ36: =I36+P36-W36-AD36 -> 0

Sheet 4일
A1: 서 울 탁 주 강 동 연 합 제 조 장
A3: 현 황 일 보 | AI3: ='3일'!AI3:AW4+1 -> 46116
B5: 1.주료사입현황
B6: 이월수량 | J6: 당일사입수량 | R6: 계 | Z6: 당일제성수량 | AH6: 당일 잔수량 | AP6: 적요
B8: ='3일'!AH8 -> 0 | R8: =B8+J8 -> 0 | AH8: =R8-Z8 -> 0 | AY8: =AH8 -> 0
B11: 2.주류제성 및 출고현황
B12: 이월수량 | I12: 당일제성수량 | Q12: 계 | Y12: 당일판매수량 | AH12: 당일 잔수량 | AP12: 적요
B14: ='3일'!AH14 -> 0 | I14: =Z8*4910 -> 0 | Q14: =B14+I14 -> 0 | AH14: =Q14-Y15 -> 0
Y15: =Y14*0.75 -> 0
B17: 3.주류제성 및 출고현황
B18: 익일 보쌈 | E18: 보쌈 | I18: 입국 | M18: 1단 | U18: 2단 1일 | Y18: 2단 2일 | AC18: 3일 이상 | AG18: 4일 이상 | AK18: 5일 이상 | AO18: 6일 이상 | AS18: 계
M19: 1일 | Q19: 2일
B20: 0 | E20: 0 | I20: ='3일'!E20 -> 0 | M20: ='3일'!I20 -> 0 | Q20: ='3일'!Q20+'3일'!M22-'4일'!J8 -> 0 | U20: =J8 -> 0 | Y20: ='3일'!U20 -> 0 | AC20: ='3일'!Y20 -> 0 | AG20: =AY21 -> 0 | AK20: 0 | AO20: 0 | AS20: =AH8 -> 0
AY21: =AH8-U20-Y20-AC20 -> 0
B22: 0 | E22: 0 | I22: ='3일'!E22 -> 0 | M22: ='3일'!I22 -> 0 | AY22: =AG20 -> 0
B25: 4.원료 및 연료수불상황 | O25: =U20*8 -> 0 | P25: =Y20*3 -> 0 | R25: =AC20*3 -> 0
B26: 구분 | H26: 백미 | N26: 팽화미 | T26: 올리고당 | Z26: 효모 | AF26: 곡자 | AL26: 감미 | AR26: 구연산
B27: 이월수량 | H27: ='3일'!H30:M30 -> 0 | N27: ='3일'!N30:S30 -> 0 | T27: ='3일'!T30:Y30 -> 0 | Z27: ='3일'!Z30:AE30 -> 0 | AF27: ='3일'!AF30:AK30 -> 0 | AL27: ='3일'!AL30:AQ30 -> 0 | AR27: ='3일'!AR30:AW30 -> 0
B28: 당일구입
B29: 당일사용 | H29: =J8*280/40 -> 0 | N29: =SUM(N25:S25) -> 0 | T29: =AC20*72 -> 0 | Z29: =M20*500+Z31 -> 0 | AF29: =J8*4 -> 0 | AL29: =Z8*545 -> 0 | AR29: =Z8*95 -> 0
B30: 잔량 | H30: =H27+H28-H29 -> 0 | N30: =N27+N28-N29 -> 0 | T30: =T27+T28-T29 -> 0 | Z30: =Z27+Z28-Z29 -> 0 | AF30: =AF27+AF28-AF29 -> 0 | AL30: =AL27+AL28-AL29 -> 0 | AR30: =AR27+AR28-AR29 -> 0
B33: 6. 용기, 마개
I34: 전일잔량 | P34: 입고 | W34: 출고 | AD34: 파손 | AJ34: 파손재고 | AQ34: 금일재고
B35: 용기 | I35: ='3일'!AQ35 -> 0 | P35: 0 | W35: =Y14 -> 0 | AJ35: =AD35+'3일'!AJ35:AP35 -> 0 | AQ35: =I35+P35-W35-AD35 -> 0
B36: 마개 | I36: ='3일'!AQ36 -> 0 | P36: =BA36*90000 -> 0 | W36: =W35 -> 0 | AJ36: =AD36+'3일'!AJ36:AP36 -> 0 | AQ36: =I36+P36-W36-AD36 -> 0

Sheet 5일
A1: 서 울 탁 주 강 동 연 합 제 조 장
A3: 현 황 일 보 | AI3: ='3일'!AI3:AW4+2 -> 46117
B5: 1.주료사입현황
B6: 이월수량 | J6: 당일사입수량 | R6: 계 | Z6: 당일제성수량 | AH6: 당일 잔수량 | AP6: 적요
B8: ='4일'!AH8 -> 0 | R8: =B8+J8 -> 0 | AH8: =R8-Z8 -> 0 | AY8: =AH8 -> 0
B11: 2.주류제성 및 출고현황
B12: 이월수량 | I12: 당일제성수량 | Q12: 계 | Y12: 당일판매수량 | AH12: 당일 잔수량 | AP12: 적요
B14: ='4일'!AH14 -> 0 | I14: =Z8*4910 -> 0 | Q14: =B14+I14 -> 0 | AH14: =Q14-Y15 -> 0
Y15: =Y14*0.75 -> 0
B17: 3.주류제성 및 출고현황
B18: 익일 보쌈 | E18: 보쌈 | I18: 입국 | M18: 1단 | U18: 2단 1일 | Y18: 2단 2일 | AC18: 3일 이상 | AG18: 4일 이상 | AK18: 5일 이상 | AO18: 6일 이상 | AS18: 계
M19: 1일 | Q19: 2일
I20: ='4일'!E20 -> 0 | M20: ='4일'!I20 -> 0 | Q20: ='4일'!Q20+'4일'!M22-'5일'!J8 -> 0 | U20: =J8 -> 0 | Y20: ='4일'!U20 -> 0 | AC20: ='4일'!Y20 -> 0 | AG20: =AY21 -> 0 | AK20: 0 | AO20: 0 | AS20: =AH8 -> 0
AY21: =AH8-U20-Y20-AC20 -> 0
I22: ='4일'!E22 -> 0 | M22: ='4일'!I22 -> 0 | AY22: =AG20 -> 0
B25: 4.원료 및 연료수불상황 | O25: =U20*8 -> 0 | P25: =Y20*3 -> 0 | R25: =AC20*3 -> 0
B26: 구분 | H26: 백미 | N26: 팽화미 | T26: 올리고당 | Z26: 효모 | AF26: 곡자 | AL26: 감미 | AR26: 구연산
B27: 이월수량 | H27: ='4일'!H30:M30 -> 0 | N27: ='4일'!N30:S30 -> 0 | T27: ='4일'!T30:Y30 -> 0 | Z27: ='4일'!Z30:AE30 -> 0 | AF27: ='4일'!AF30:AK30 -> 0 | AL27: ='4일'!AL30:AQ30 -> 0 | AR27: ='4일'!AR30:AW30 -> 0
B28: 당일구입
B29: 당일사용 | H29: =J8*280/40 -> 0 | N29: =SUM(N25:S25) -> 0 | T29: =AC20*72 -> 0 | Z29: =M20*500+Z31 -> 0 | AF29: =J8*4 -> 0 | AL29: =Z8*545 -> 0 | AR29: =Z8*95 -> 0
B30: 잔량 | H30: =H27+H28-H29 -> 0 | N30: =N27+N28-N29 -> 0 | T30: =T27+T28-T29 -> 0 | Z30: =Z27+Z28-Z29 -> 0 | AF30: =AF27+AF28-AF29 -> 0 | AL30: =AL27+AL28-AL29 -> 0 | AR30: =AR27+AR28-AR29 -> 0
B33: 6. 용기, 마개
I34: 전일잔량 | P34: 입고 | W34: 출고 | AD34: 파손 | AJ34: 파손재고 | AQ34: 금일재고
B35: 용기 | I35: ='4일'!AQ35 -> 0 | W35: =Y14 -> 0 | AJ35: =AD35+'4일'!AJ35:AP35 -> 0 | AQ35: =I35+P35-W35-AD35 -> 0
B36: 마개 | I36: ='4일'!AQ36 -> 0 | P36: 0 | W36: =W35 -> 0 | AJ36: =AD36+'4일'!AJ36:AP36 -> 0 | AQ36: =I36+P36-W36-AD36 -> 0

Sheet 6일
A1: 서 울 탁 주 강 동 연 합 제 조 장
A3: 현 황 일 보 | AI3: ='5일'!AI3:AW4+1 -> 46118
B5: 1.주료사입현황
B6: 이월수량 | J6: 당일사입수량 | R6: 계 | Z6: 당일제성수량 | AH6: 당일 잔수량 | AP6: 적요
B8: ='5일'!AH8 -> 0 | R8: =B8+J8 -> 0 | AH8: =R8-Z8 -> 0 | AY8: =AH8 -> 0
B11: 2.주류제성 및 출고현황
B12: 이월수량 | I12: 당일제성수량 | Q12: 계 | Y12: 당일판매수량 | AH12: 당일 잔수량 | AP12: 적요
B14: ='5일'!AH14 -> 0 | I14: =Z8*4910 -> 0 | Q14: =B14+I14 -> 0 | AH14: =Q14-Y15 -> 0
Y15: =Y14*0.75 -> 0
B17: 3.주류제성 및 출고현황
B18: 익일 보쌈 | E18: 보쌈 | I18: 입국 | M18: 1단 | U18: 2단 1일 | Y18: 2단 2일 | AC18: 3일 이상 | AG18: 4일 이상 | AK18: 5일 이상 | AO18: 6일 이상 | AS18: 계
M19: 1일 | Q19: 2일
I20: ='5일'!E20 -> 0 | M20: ='5일'!I20 -> 0 | Q20: ='5일'!Q20+'5일'!M22-'6일'!J8 -> 0 | U20: =J8 -> 0 | Y20: ='5일'!U20 -> 0 | AC20: ='5일'!Y20 -> 0 | AG20: =AY21 -> 0 | AK20: 0 | AO20: 0 | AS20: =AH8 -> 0
AY21: =AH8-U20-Y20-AC20 -> 0
I22: ='5일'!E22 -> 0 | M22: ='5일'!I22 -> 0 | AY22: =AG20 -> 0
B25: 4.원료 및 연료수불상황 | O25: =U20*8 -> 0 | P25: =Y20*3 -> 0 | R25: =AC20*3 -> 0
B26: 구분 | H26: 백미 | N26: 팽화미 | T26: 올리고당 | Z26: 효모 | AF26: 곡자 | AL26: 감미 | AR26: 구연산
B27: 이월수량 | H27: ='5일'!H30:M30 -> 0 | N27: ='5일'!N30:S30 -> 0 | T27: ='5일'!T30:Y30 -> 0 | Z27: ='5일'!Z30:AE30 -> 0 | AF27: ='5일'!AF30:AK30 -> 0 | AL27: ='5일'!AL30:AQ30 -> 0 | AR27: ='5일'!AR30:AW30 -> 0
B28: 당일구입
B29: 당일사용 | H29: =J8*280/40 -> 0 | N29: =SUM(N25:S25) -> 0 | T29: =AC20*72 -> 0 | Z29: =M20*500+Z31 -> 0 | AF29: =J8*4 -> 0 | AL29: =Z8*545 -> 0 | AR29: =Z8*95 -> 0
B30: 잔량 | H30: =H27+H28-H29 -> 0 | N30: =N27+N28-N29 -> 0 | T30: =T27+T28-T29 -> 0 | Z30: =Z27+Z28-Z29 -> 0 | AF30: =AF27+AF28-AF29 -> 0 | AL30: =AL27+AL28-AL29 -> 0 | AR30: =AR27+AR28-AR29 -> 0
B33: 6. 용기, 마개
I34: 전일잔량 | P34: 입고 | W34: 출고 | AD34: 파손 | AJ34: 파손재고 | AQ34: 금일재고
B35: 용기 | I35: ='5일'!AQ35 -> 0 | W35: =Y14 -> 0 | AJ35: =AD35+'5일'!AJ35:AP35 -> 0 | AQ35: =I35+P35-W35-AD35 -> 0
B36: 마개 | I36: ='5일'!AQ36 -> 0 | P36: =BA36*90000 -> 0 | W36: =W35 -> 0 | AJ36: =AD36+'5일'!AJ36:AP36 -> 0 | AQ36: =I36+P36-W36-AD36 -> 0

Sheet 7일
A1: 서 울 탁 주 강 동 연 합 제 조 장
A3: 현 황 일 보 | AI3: ='5일'!AI3:AW4+2 -> 46119
B5: 1.주료사입현황
B6: 이월수량 | J6: 당일사입수량 | R6: 계 | Z6: 당일제성수량 | AH6: 당일 잔수량 | AP6: 적요
B8: ='6일'!AH8 -> 0 | R8: =B8+J8 -> 0 | AH8: =R8-Z8 -> 0 | AY8: =AH8 -> 0
B11: 2.주류제성 및 출고현황
B12: 이월수량 | I12: 당일제성수량 | Q12: 계 | Y12: 당일판매수량 | AH12: 당일 잔수량 | AP12: 적요 | AY12: =Y15/4290 -> 0
B14: ='6일'!AH14 -> 0 | I14: =Z8*4910 -> 0 | Q14: =B14+I14 -> 0 | AH14: =Q14-Y15 -> 0
Y15: =Y14*0.75 -> 0
B17: 3.주류제성 및 출고현황
B18: 익일 보쌈 | E18: 보쌈 | I18: 입국 | M18: 1단 | U18: 2단 1일 | Y18: 2단 2일 | AC18: 3일 이상 | AG18: 4일 이상 | AK18: 5일 이상 | AO18: 6일 이상 | AS18: 계
M19: 1일 | Q19: 2일
I20: ='6일'!E20 -> 0 | M20: ='6일'!I20 -> 0 | Q20: ='6일'!Q20+'6일'!M22-'7일'!J8 -> 0 | U20: =J8 -> 0 | Y20: ='6일'!U20 -> 0 | AC20: ='6일'!Y20 -> 0 | AG20: =AY21 -> 0 | AK20: 0 | AO20: 0 | AS20: =AH8 -> 0
AY21: =AH8-U20-Y20-AC20 -> 0
I22: ='6일'!E22 -> 0 | M22: ='6일'!I22 -> 0 | AY22: =AG20 -> 0
B25: 4.원료 및 연료수불상황 | O25: =U20*8 -> 0 | P25: =Y20*3 -> 0 | R25: =AC20*3 -> 0
B26: 구분 | H26: 백미 | N26: 팽화미 | T26: 올리고당 | Z26: 효모 | AF26: 곡자 | AL26: 감미 | AR26: 구연산
B27: 이월수량 | H27: ='6일'!H30:M30 -> 0 | N27: ='6일'!N30:S30 -> 0 | T27: ='6일'!T30:Y30 -> 0 | Z27: ='6일'!Z30:AE30 -> 0 | AF27: ='6일'!AF30:AK30 -> 0 | AL27: ='6일'!AL30:AQ30 -> 0 | AR27: ='6일'!AR30:AW30 -> 0
B28: 당일구입
B29: 당일사용 | H29: =J8*280/40 -> 0 | N29: =SUM(N25:S25) -> 0 | T29: =AC20*72 -> 0 | Z29: =M20*500+Z31 -> 0 | AF29: =J8*4 -> 0 | AL29: =Z8*545 -> 0 | AR29: =Z8*95 -> 0
B30: 잔량 | H30: =H27+H28-H29 -> 0 | N30: =N27+N28-N29 -> 0 | T30: =T27+T28-T29 -> 0 | Z30: =Z27+Z28-Z29 -> 0 | AF30: =AF27+AF28-AF29 -> 0 | AL30: =AL27+AL28-AL29 -> 0 | AR30: =AR27+AR28-AR29 -> 0
B33: 6. 용기, 마개
I34: 전일잔량 | P34: 입고 | W34: 출고 | AD34: 파손 | AJ34: 파손재고 | AQ34: 금일재고
B35: 용기 | I35: ='6일'!AQ35 -> 0 | W35: =Y14 -> 0 | AJ35: =AD35+'6일'!AJ35:AP35 -> 0 | AQ35: =I35+P35-W35-AD35 -> 0
B36: 마개 | I36: ='6일'!AQ36 -> 0 | P36: =BA36*90000 -> 0 | W36: =W35 -> 0 | AJ36: =AD36+'6일'!AJ36:AP36 -> 0 | AQ36: =I36+P36-W36-AD36 -> 0
AO38: =AO37-AF37 -> 0

Sheet 8일
A1: 서 울 탁 주 강 동 연 합 제 조 장
A3: 현 황 일 보 | AI3: ='5일'!AI3:AW4+3 -> 46120
B5: 1.주료사입현황
B6: 이월수량 | J6: 당일사입수량 | R6: 계 | Z6: 당일제성수량 | AH6: 당일 잔수량 | AP6: 적요
B8: ='7일'!AH8 -> 0 | R8: =B8+J8 -> 0 | AH8: =R8-Z8 -> 0 | AY8: =AH8 -> 0
B11: 2.주류제성 및 출고현황
B12: 이월수량 | I12: 당일제성수량 | Q12: 계 | Y12: 당일판매수량 | AH12: 당일 잔수량 | AP12: 적요
B14: ='7일'!AH14 -> 0 | I14: =Z8*4910 -> 0 | Q14: =B14+I14 -> 0 | AH14: =Q14-Y15 -> 0
Y15: =Y14*0.75 -> 0
B17: 3.주류제성 및 출고현황
B18: 익일 보쌈 | E18: 보쌈 | I18: 입국 | M18: 1단 | U18: 2단 1일 | Y18: 2단 2일 | AC18: 3일 이상 | AG18: 4일 이상 | AK18: 5일 이상 | AO18: 6일 이상 | AS18: 계
M19: 1일 | Q19: 2일
I20: ='7일'!E20 -> 0 | M20: ='7일'!I20 -> 0 | Q20: ='7일'!Q20+'7일'!M22-'8일'!J8 -> 0 | U20: =J8 -> 0 | Y20: ='7일'!U20 -> 0 | AC20: ='7일'!Y20 -> 0 | AG20: =AY21 -> 0 | AK20: 0 | AO20: 0 | AS20: =AH8 -> 0
AY21: =AH8-U20-Y20-AC20 -> 0
I22: ='7일'!E22 -> 0 | M22: ='7일'!I22 -> 0 | AY22: =AG20 -> 0
B25: 4.원료 및 연료수불상황 | O25: =U20*8 -> 0 | P25: =Y20*3 -> 0 | R25: =AC20*3 -> 0
B26: 구분 | H26: 백미 | N26: 팽화미 | T26: 올리고당 | Z26: 효모 | AF26: 곡자 | AL26: 감미 | AR26: 구연산
B27: 이월수량 | H27: ='7일'!H30:M30 -> 0 | N27: ='7일'!N30:S30 -> 0 | T27: ='7일'!T30:Y30 -> 0 | Z27: ='7일'!Z30:AE30 -> 0 | AF27: ='7일'!AF30:AK30 -> 0 | AL27: ='7일'!AL30:AQ30 -> 0 | AR27: ='7일'!AR30:AW30 -> 0
B28: 당일구입
B29: 당일사용 | H29: =J8*280/40 -> 0 | N29: =SUM(N25:S25) -> 0 | T29: =AC20*72 -> 0 | Z29: =M20*500+Z31 -> 0 | AF29: =J8*4 -> 0 | AL29: =Z8*545 -> 0 | AR29: =Z8*95 -> 0
B30: 잔량 | H30: =H27+H28-H29 -> 0 | N30: =N27+N28-N29 -> 0 | T30: =T27+T28-T29 -> 0 | Z30: =Z27+Z28-Z29 -> 0 | AF30: =AF27+AF28-AF29 -> 0 | AL30: =AL27+AL28-AL29 -> 0 | AR30: =AR27+AR28-AR29 -> 0
B33: 6. 용기, 마개
I34: 전일잔량 | P34: 입고 | W34: 출고 | AD34: 파손 | AJ34: 파손재고 | AQ34: 금일재고
B35: 용기 | I35: ='7일'!AQ35 -> 0 | W35: =Y14 -> 0 | AJ35: =AD35+'7일'!AJ35:AP35 -> 0 | AQ35: =I35+P35-W35-AD35 -> 0
B36: 마개 | I36: ='7일'!AQ36 -> 0 | P36: =BA36*90000 -> 0 | W36: =W35 -> 0 | AJ36: =AD36+'7일'!AJ36:AP36 -> 0 | AQ36: =I36+P36-W36-AD36 -> 0

Sheet 9일
A1: 서 울 탁 주 강 동 연 합 제 조 장
A3: 현 황 일 보 | AI3: ='5일'!AI3:AW4+4 -> 46121
B5: 1.주료사입현황
B6: 이월수량 | J6: 당일사입수량 | R6: 계 | Z6: 당일제성수량 | AH6: 당일 잔수량 | AP6: 적요
B8: ='8일'!AH8 -> 0 | R8: =B8+J8 -> 0 | AH8: =R8-Z8 -> 0 | AY8: =AH8 -> 0
B11: 2.주류제성 및 출고현황
B12: 이월수량 | I12: 당일제성수량 | Q12: 계 | Y12: 당일판매수량 | AH12: 당일 잔수량 | AP12: 적요
B14: ='8일'!AH14 -> 0 | I14: =Z8*4910 -> 0 | Q14: =B14+I14 -> 0 | AH14: =Q14-Y15 -> 0
Y15: =Y14*0.75 -> 0
B17: 3.주류제성 및 출고현황
B18: 익일 보쌈 | E18: 보쌈 | I18: 입국 | M18: 1단 | U18: 2단 1일 | Y18: 2단 2일 | AC18: 3일 이상 | AG18: 4일 이상 | AK18: 5일 이상 | AO18: 6일 이상 | AS18: 계
M19: 1일 | Q19: 2일
I20: ='8일'!E20 -> 0 | M20: ='8일'!I20 -> 0 | Q20: ='8일'!Q20+'8일'!M22-'9일'!J8 -> 0 | U20: =J8 -> 0 | Y20: ='8일'!U20 -> 0 | AC20: ='8일'!Y20 -> 0 | AG20: =AY21 -> 0 | AK20: 0 | AO20: 0 | AS20: =AH8 -> 0
AY21: =AH8-U20-Y20-AC20 -> 0
I22: ='8일'!E22 -> 0 | M22: ='8일'!I22 -> 0 | AY22: =AH8-U20-Y20-AC20 -> 0
B25: 4.원료 및 연료수불상황 | O25: =U20*8 -> 0 | P25: =Y20*3 -> 0 | R25: =AC20*3 -> 0
B26: 구분 | H26: 백미 | N26: 팽화미 | T26: 올리고당 | Z26: 효모 | AF26: 곡자 | AL26: 감미 | AR26: 구연산
B27: 이월수량 | H27: ='8일'!H30:M30 -> 0 | N27: ='8일'!N30:S30 -> 0 | T27: ='8일'!T30:Y30 -> 0 | Z27: ='8일'!Z30:AE30 -> 0 | AF27: ='8일'!AF30:AK30 -> 0 | AL27: ='8일'!AL30:AQ30 -> 0 | AR27: ='8일'!AR30:AW30 -> 0
B28: 당일구입
B29: 당일사용 | H29: =J8*280/40 -> 0 | N29: =SUM(N25:S25) -> 0 | T29: =AC20*72 -> 0 | Z29: =M20*500+Z31 -> 0 | AF29: =J8*4 -> 0 | AL29: =Z8*545 -> 0 | AR29: =Z8*95 -> 0
B30: 잔량 | H30: =H27+H28-H29 -> 0 | N30: =N27+N28-N29 -> 0 | T30: =T27+T28-T29 -> 0 | Z30: =Z27+Z28-Z29 -> 0 | AF30: =AF27+AF28-AF29 -> 0 | AL30: =AL27+AL28-AL29 -> 0 | AR30: =AR27+AR28-AR29 -> 0
B33: 6. 용기, 마개
I34: 전일잔량 | P34: 입고 | W34: 출고 | AD34: 파손 | AJ34: 파손재고 | AQ34: 금일재고
B35: 용기 | I35: ='8일'!AQ35 -> 0 | W35: =Y14 -> 0 | AJ35: =AD35+'8일'!AJ35:AP35 -> 0 | AQ35: =I35+P35-W35-AD35 -> 0
B36: 마개 | I36: ='8일'!AQ36 -> 0 | W36: =W35 -> 0 | AJ36: =AD36+'8일'!AJ36:AP36 -> 0 | AQ36: =I36+P36-W36-AD36 -> 0

Sheet 10일
A1: 서 울 탁 주 강 동 연 합 제 조 장
A3: 현 황 일 보 | AI3: ='5일'!AI3:AW4+5 -> 46122
B5: 1.주료사입현황
B6: 이월수량 | J6: 당일사입수량 | R6: 계 | Z6: 당일제성수량 | AH6: 당일 잔수량 | AP6: 적요
B8: ='9일'!AH8 -> 0 | R8: =B8+J8 -> 0 | AH8: =R8-Z8 -> 0 | AY8: =AH8 -> 0
B11: 2.주류제성 및 출고현황
B12: 이월수량 | I12: 당일제성수량 | Q12: 계 | Y12: 당일판매수량 | AH12: 당일 잔수량 | AP12: 적요
B14: ='9일'!AH14 -> 0 | I14: =Z8*4910 -> 0 | Q14: =B14+I14 -> 0 | AH14: =Q14-Y15 -> 0
Y15: =Y14*0.75 -> 0
B17: 3.주류제성 및 출고현황
B18: 익일 보쌈 | E18: 보쌈 | I18: 입국 | M18: 1단 | U18: 2단 1일 | Y18: 2단 2일 | AC18: 3일 이상 | AG18: 4일 이상 | AK18: 5일 이상 | AO18: 6일 이상 | AS18: 계
M19: 1일 | Q19: 2일
I20: ='9일'!E20 -> 0 | M20: ='9일'!I20 -> 0 | Q20: ='9일'!Q20+'9일'!M22-'10일'!J8 -> 0 | U20: =J8 -> 0 | Y20: ='9일'!U20 -> 0 | AC20: ='9일'!Y20 -> 0 | AG20: =AY21 -> 0 | AK20: 0 | AO20: 0 | AS20: =AH8 -> 0
AY21: =AH8-U20-Y20-AC20 -> 0
I22: ='9일'!E22 -> 0 | M22: ='9일'!I22 -> 0 | AY22: =AG20 -> 0
B25: 4.원료 및 연료수불상황 | O25: =U20*8 -> 0 | P25: =Y20*3 -> 0 | R25: =AC20*3 -> 0
B26: 구분 | H26: 백미 | N26: 팽화미 | T26: 올리고당 | Z26: 효모 | AF26: 곡자 | AL26: 감미 | AR26: 구연산
B27: 이월수량 | H27: ='9일'!H30:M30 -> 0 | N27: ='9일'!N30:S30 -> 0 | T27: ='9일'!T30:Y30 -> 0 | Z27: ='9일'!Z30:AE30 -> 0 | AF27: ='9일'!AF30:AK30 -> 0 | AL27: ='9일'!AL30:AQ30 -> 0 | AR27: ='9일'!AR30:AW30 -> 0
B28: 당일구입
B29: 당일사용 | H29: =J8*280/40 -> 0 | N29: =SUM(N25:S25) -> 0 | T29: =AC20*72 -> 0 | Z29: =M20*500+Z31 -> 0 | AF29: =J8*4 -> 0 | AL29: =Z8*545 -> 0 | AR29: =Z8*95 -> 0
B30: 잔량 | H30: =H27+H28-H29 -> 0 | N30: =N27+N28-N29 -> 0 | T30: =T27+T28-T29 -> 0 | Z30: =Z27+Z28-Z29 -> 0 | AF30: =AF27+AF28-AF29 -> 0 | AL30: =AL27+AL28-AL29 -> 0 | AR30: =AR27+AR28-AR29 -> 0
B32: 6. 용기, 마개
I33: 전일잔량 | P33: 입고 | W33: 출고 | AD33: 파손 | AJ33: 파손재고 | AQ33: 금일재고
B34: 용기 | I34: ='9일'!AQ35 -> 0 | W34: =Y14 -> 0 | AJ34: =AD34+'9일'!AJ35:AP35 -> 0 | AQ34: =I34+P34-W34-AD34 -> 0
B35: 마개 | I35: ='9일'!AQ36 -> 0 | P35: 0 | W35: =W34 -> 0 | AJ35: =AD35+'9일'!AJ36:AP36 -> 0 | AQ35: =I35+P35-W35-AD35 -> 0

Sheet 11일
A1: 서 울 탁 주 강 동 연 합 제 조 장
A3: 현 황 일 보 | AI3: ='5일'!AI3:AW4+6 -> 46123
B5: 1.주료사입현황
B6: 이월수량 | J6: 당일사입수량 | R6: 계 | Z6: 당일제성수량 | AH6: 당일 잔수량 | AP6: 적요
B8: ='10일'!AH8 -> 0 | R8: =B8+J8 -> 0 | AH8: =R8-Z8 -> 0 | AY8: =AH8 -> 0
B11: 2.주류제성 및 출고현황
B12: 이월수량 | I12: 당일제성수량 | Q12: 계 | Y12: 당일판매수량 | AH12: 당일 잔수량 | AP12: 적요
B14: ='10일'!AH14 -> 0 | I14: =Z8*4910 -> 0 | Q14: =B14+I14 -> 0 | AH14: =Q14-Y15 -> 0
Y15: =Y14*0.75 -> 0
B17: 3.주류제성 및 출고현황
B18: 익일 보쌈 | E18: 보쌈 | I18: 입국 | M18: 1단 | U18: 2단 1일 | Y18: 2단 2일 | AC18: 3일 이상 | AG18: 4일 이상 | AK18: 5일 이상 | AO18: 6일 이상 | AS18: 계
M19: 1일 | Q19: 2일
I20: ='10일'!E20 -> 0 | M20: ='10일'!I20 -> 0 | Q20: ='10일'!Q20+'10일'!M22-'11일'!J8 -> 0 | U20: =J8 -> 0 | Y20: ='10일'!U20 -> 0 | AC20: ='10일'!Y20 -> 0 | AG20: =AY21 -> 0 | AK20: 0 | AO20: 0 | AS20: =AH8 -> 0
AY21: =AH8-U20-Y20-AC20 -> 0
I22: ='10일'!E22 -> 0 | M22: ='10일'!I22 -> 0 | AY22: =AG20 -> 0
B25: 4.원료 및 연료수불상황 | O25: =U20*8 -> 0 | P25: =Y20*3 -> 0 | R25: =AC20*3 -> 0
B26: 구분 | H26: 백미 | N26: 팽화미 | T26: 올리고당 | Z26: 효모 | AF26: 곡자 | AL26: 감미 | AR26: 구연산
B27: 이월수량 | H27: ='10일'!H30:M30 -> 0 | N27: ='10일'!N30:S30 -> 0 | T27: ='10일'!T30:Y30 -> 0 | Z27: ='10일'!Z30:AE30 -> 0 | AF27: ='10일'!AF30:AK30 -> 0 | AL27: ='10일'!AL30:AQ30 -> 0 | AR27: ='10일'!AR30:AW30 -> 0
B28: 당일구입
B29: 당일사용 | H29: =J8*280/40 -> 0 | N29: =SUM(N25:S25) -> 0 | T29: =AC20*72 -> 0 | Z29: =M20*500+Z31 -> 0 | AF29: =J8*4 -> 0 | AL29: =Z8*545 -> 0 | AR29: =Z8*95 -> 0
B30: 잔량 | H30: =H27+H28-H29 -> 0 | N30: =N27+N28-N29 -> 0 | T30: =T27+T28-T29 -> 0 | Z30: =Z27+Z28-Z29 -> 0 | AF30: =AF27+AF28-AF29 -> 0 | AL30: =AL27+AL28-AL29 -> 0 | AR30: =AR27+AR28-AR29 -> 0
B33: 6. 용기, 마개 | P33: 2 | T33: 1
I34: 전일잔량 | P34: 입고 | W34: 출고 | AD34: 파손 | AJ34: 파손재고 | AQ34: 금일재고
B35: 용기 | I35: ='10일'!AQ34 -> 0 | P35: 0 | W35: =Y14 -> 0 | AJ35: =AD35+'10일'!AJ34:AP34 -> 0 | AQ35: =I35+P35-W35-AD35 -> 0
B36: 마개 | I36: ='10일'!AQ35 -> 0 | P36: 0 | W36: =W35 -> 0 | AJ36: =AD36+'10일'!AJ35:AP35 -> 0 | AQ36: =I36+P36-W36-AD36 -> 0

Sheet 12일
A1: 서 울 탁 주 강 동 연 합 제 조 장
A3: 현 황 일 보 | AI3: ='5일'!AI3:AW4+7 -> 46124
B5: 1.주료사입현황
B6: 이월수량 | J6: 당일사입수량 | R6: 계 | Z6: 당일제성수량 | AH6: 당일 잔수량 | AP6: 적요
B8: ='11일'!AH8 -> 0 | R8: =B8+J8 -> 0 | AH8: =R8-Z8 -> 0 | AY8: =AH8 -> 0
B11: 2.주류제성 및 출고현황
B12: 이월수량 | I12: 당일제성수량 | Q12: 계 | Y12: 당일판매수량 | AH12: 당일 잔수량 | AP12: 적요
B14: ='11일'!AH14 -> 0 | I14: =Z8*4910 -> 0 | Q14: =B14+I14 -> 0 | AH14: =Q14-Y15 -> 0
Y15: =Y14*0.75 -> 0
B17: 3.주류제성 및 출고현황
B18: 익일 보쌈 | E18: 보쌈 | I18: 입국 | M18: 1단 | U18: 2단 1일 | Y18: 2단 2일 | AC18: 3일 이상 | AG18: 4일 이상 | AK18: 5일 이상 | AO18: 6일 이상 | AS18: 계
M19: 1일 | Q19: 2일
I20: ='11일'!E20 -> 0 | M20: ='11일'!I20 -> 0 | Q20: ='11일'!Q20+'11일'!M22-'12일'!J8 -> 0 | U20: =J8 -> 0 | Y20: ='11일'!U20 -> 0 | AC20: ='11일'!Y20 -> 0 | AG20: =AY21 -> 0 | AK20: 0 | AO20: 0 | AS20: =AH8 -> 0
AY21: =AH8-U20-Y20-AC20 -> 0
I22: ='11일'!E22 -> 0 | M22: ='11일'!I22 -> 0 | AY22: =AG20 -> 0
B25: 4.원료 및 연료수불상황 | O25: =U20*8 -> 0 | P25: =Y20*3 -> 0 | R25: =AC20*3 -> 0
B26: 구분 | H26: 백미 | N26: 팽화미 | T26: 올리고당 | Z26: 효모 | AF26: 곡자 | AL26: 감미 | AR26: 구연산
B27: 이월수량 | H27: ='11일'!H30:M30 -> 0 | N27: ='11일'!N30:S30 -> 0 | T27: ='11일'!T30:Y30 -> 0 | Z27: ='11일'!Z30:AE30 -> 0 | AF27: ='11일'!AF30:AK30 -> 0 | AL27: ='11일'!AL30:AQ30 -> 0 | AR27: ='11일'!AR30:AW30 -> 0
B28: 당일구입
B29: 당일사용 | H29: =J8*280/40 -> 0 | N29: =SUM(N25:S25) -> 0 | T29: =AC20*72 -> 0 | Z29: =M20*500+Z31 -> 0 | AF29: =J8*4 -> 0 | AL29: =Z8*545 -> 0 | AR29: =Z8*95 -> 0
B30: 잔량 | H30: =H27+H28-H29 -> 0 | N30: =N27+N28-N29 -> 0 | T30: =T27+T28-T29 -> 0 | Z30: =Z27+Z28-Z29 -> 0 | AF30: =AF27+AF28-AF29 -> 0 | AL30: =AL27+AL28-AL29 -> 0 | AR30: =AR27+AR28-AR29 -> 0
B33: 6. 용기, 마개 | P33: 2 | T33: 0
I34: 전일잔량 | P34: 입고 | W34: 출고 | AD34: 파손 | AJ34: 파손재고 | AQ34: 금일재고
B35: 용기 | I35: ='11일'!AQ35 -> 0 | W35: =Y14 -> 0 | AJ35: =AD35+'11일'!AJ35:AP35 -> 0 | AQ35: =I35+P35-W35-AD35 -> 0
B36: 마개 | I36: ='11일'!AQ36 -> 0 | P36: =T33*672000 -> 0 | W36: =W35 -> 0 | AJ36: =AD36+'11일'!AJ36:AP36 -> 0 | AQ36: =I36+P36-W36-AD36 -> 0

Sheet 13일
A1: 서 울 탁 주 강 동 연 합 제 조 장
A3: 현 황 일 보 | AI3: ='5일'!AI3:AW4+8 -> 46125
B5: 1.주료사입현황
B6: 이월수량 | J6: 당일사입수량 | R6: 계 | Z6: 당일제성수량 | AH6: 당일 잔수량 | AP6: 적요
B8: ='12일'!AH8 -> 0 | R8: =B8+J8 -> 0 | AH8: =R8-Z8 -> 0 | AY8: =AH8 -> 0
B11: 2.주류제성 및 출고현황
B12: 이월수량 | I12: 당일제성수량 | Q12: 계 | Y12: 당일판매수량 | AH12: 당일 잔수량 | AP12: 적요
B14: ='12일'!AH14 -> 0 | I14: =Z8*4910 -> 0 | Q14: =B14+I14 -> 0 | AH14: =Q14-Y15 -> 0
Y15: =Y14*0.75 -> 0
B17: 3.주류제성 및 출고현황
B18: 익일 보쌈 | E18: 보쌈 | I18: 입국 | M18: 1단 | U18: 2단 1일 | Y18: 2단 2일 | AC18: 3일 이상 | AG18: 4일 이상 | AK18: 5일 이상 | AO18: 6일 이상 | AS18: 계
M19: 1일 | Q19: 2일
I20: ='12일'!E20 -> 0 | M20: ='12일'!I20 -> 0 | Q20: ='12일'!Q20+'12일'!M22-'13일'!J8 -> 0 | U20: =J8 -> 0 | Y20: ='12일'!U20 -> 0 | AC20: ='12일'!Y20 -> 0 | AG20: =AY21 -> 0 | AK20: 0 | AO20: 0 | AS20: =AH8 -> 0
AY21: =AH8-U20-Y20-AC20 -> 0
I22: ='12일'!E22 -> 0 | M22: ='12일'!I22 -> 0 | AY22: =AG20 -> 0
AY23: 0
B25: 4.원료 및 연료수불상황 | O25: =U20*8 -> 0 | P25: =Y20*3 -> 0 | R25: =AC20*3 -> 0
B26: 구분 | H26: 백미 | N26: 팽화미 | T26: 올리고당 | Z26: 효모 | AF26: 곡자 | AL26: 감미 | AR26: 구연산
B27: 이월수량 | H27: ='12일'!H30:M30 -> 0 | N27: ='12일'!N30:S30 -> 0 | T27: ='12일'!T30:Y30 -> 0 | Z27: ='12일'!Z30:AE30 -> 0 | AF27: ='12일'!AF30:AK30 -> 0 | AL27: ='12일'!AL30:AQ30 -> 0 | AR27: ='12일'!AR30:AW30 -> 0
B28: 당일구입
B29: 당일사용 | H29: =J8*280/40 -> 0 | N29: =SUM(O25:S25) -> 0 | T29: =AC20*72 -> 0 | Z29: =M20*500+Z31 -> 0 | AF29: =J8*4 -> 0 | AL29: =Z8*545 -> 0 | AR29: =Z8*95 -> 0
B30: 잔량 | H30: =H27+H28-H29 -> 0 | N30: =N27+N28-N29 -> 0 | T30: =T27+T28-T29 -> 0 | Z30: =Z27+Z28-Z29 -> 0 | AF30: =AF27+AF28-AF29 -> 0 | AL30: =AL27+AL28-AL29 -> 0 | AR30: =AR27+AR28-AR29 -> 0
B33: 6. 용기, 마개 | P33: 3
I34: 전일잔량 | P34: 입고 | W34: 출고 | AD34: 파손 | AJ34: 파손재고 | AQ34: 금일재고
B35: 용기 | I35: ='12일'!AQ35 -> 0 | W35: =Y14 -> 0 | AJ35: =AD35+'12일'!AJ35:AP35 -> 0 | AQ35: =I35+P35-W35-AD35 -> 0
B36: 마개 | I36: ='12일'!AQ36 -> 0 | P36: =T33*672000 -> 0 | W36: =W35 -> 0 | AJ36: =AD36+'12일'!AJ36:AP36 -> 0 | AQ36: =I36+P36-W36-AD36 -> 0

Sheet 14일
A1: 서 울 탁 주 강 동 연 합 제 조 장
A3: 현 황 일 보 | AI3: ='5일'!AI3:AW4+9 -> 46126
B5: 1.주료사입현황
B6: 이월수량 | J6: 당일사입수량 | R6: 계 | Z6: 당일제성수량 | AH6: 당일 잔수량 | AP6: 적요
B8: ='13일'!AH8 -> 0 | R8: =B8+J8 -> 0 | AH8: =R8-Z8 -> 0 | AY8: =AH8 -> 0
B11: 2.주류제성 및 출고현황
B12: 이월수량 | I12: 당일제성수량 | Q12: 계 | Y12: 당일판매수량 | AH12: 당일 잔수량 | AP12: 적요
B14: ='13일'!AH14 -> 0 | I14: =Z8*4910 -> 0 | Q14: =B14+I14 -> 0 | AH14: =Q14-Y15 -> 0
Y15: =Y14*0.75 -> 0
B17: 3.주류제성 및 출고현황
B18: 익일 보쌈 | E18: 보쌈 | I18: 입국 | M18: 1단 | U18: 2단 1일 | Y18: 2단 2일 | AC18: 3일 이상 | AG18: 4일 이상 | AK18: 5일 이상 | AO18: 6일 이상 | AS18: 계
M19: 1일 | Q19: 2일
I20: ='13일'!E20 -> 0 | M20: ='13일'!I20 -> 0 | Q20: ='13일'!Q20+'13일'!M22-'14일'!J8 -> 0 | U20: =J8 -> 0 | Y20: ='13일'!U20 -> 0 | AC20: ='13일'!Y20 -> 0 | AG20: =AY21 -> 0 | AK20: 0 | AO20: 0 | AS20: =AH8 -> 0
AY21: =AH8-U20-Y20-AC20 -> 0
I22: ='13일'!E22 -> 0 | M22: ='13일'!I22 -> 0 | AY22: =AG20 -> 0
B25: 4.원료 및 연료수불상황 | O25: =U20*8 -> 0 | P25: =Y20*3 -> 0 | R25: =AC20*3 -> 0
B26: 구분 | H26: 백미 | N26: 팽화미 | T26: 올리고당 | Z26: 효모 | AF26: 곡자 | AL26: 감미 | AR26: 구연산
B27: 이월수량 | H27: ='13일'!H30:M30 -> 0 | N27: ='13일'!N30:S30 -> 0 | T27: ='13일'!T30:Y30 -> 0 | Z27: ='13일'!Z30:AE30 -> 0 | AF27: ='13일'!AF30:AK30 -> 0 | AL27: ='13일'!AL30:AQ30 -> 0 | AR27: ='13일'!AR30:AW30 -> 0
B28: 당일구입
B29: 당일사용 | H29: =J8*280/40 -> 0 | N29: =SUM(N25:S25) -> 0 | T29: =AC20*72 -> 0 | Z29: =M20*500+Z31 -> 0 | AF29: =J8*4 -> 0 | AL29: =Z8*545 -> 0 | AR29: =Z8*95 -> 0
B30: 잔량 | H30: =H27+H28-H29 -> 0 | N30: =N27+N28-N29 -> 0 | T30: =T27+T28-T29 -> 0 | Z30: =Z27+Z28-Z29 -> 0 | AF30: =AF27+AF28-AF29 -> 0 | AL30: =AL27+AL28-AL29 -> 0 | AR30: =AR27+AR28-AR29 -> 0
B33: 6. 용기, 마개 | P33: 0
I34: 전일잔량 | P34: 입고 | W34: 출고 | AD34: 파손 | AJ34: 파손재고 | AQ34: 금일재고
B35: 용기 | I35: ='13일'!AQ35 -> 0 | W35: =Y14 -> 0 | AJ35: =AD35+'13일'!AJ35:AP35 -> 0 | AQ35: =I35+P35-W35-AD35 -> 0
B36: 마개 | I36: ='13일'!AQ36 -> 0 | P36: =T33*672000 -> 0 | W36: =W35 -> 0 | AJ36: =AD36+'13일'!AJ36:AP36 -> 0 | AQ36: =I36+P36-W36-AD36 -> 0

Sheet 15일
A1: 서 울 탁 주 강 동 연 합 제 조 장
A3: 현 황 일 보 | AI3: ='5일'!AI3:AW4+10 -> 46127
B5: 1.주료사입현황
B6: 이월수량 | J6: 당일사입수량 | R6: 계 | Z6: 당일제성수량 | AH6: 당일 잔수량 | AP6: 적요
B8: ='14일'!AH8 -> 0 | R8: =B8+J8 -> 0 | AH8: =R8-Z8 -> 0 | AY8: =AH8 -> 0
B11: 2.주류제성 및 출고현황
B12: 이월수량 | I12: 당일제성수량 | Q12: 계 | Y12: 당일판매수량 | AH12: 당일 잔수량 | AP12: 적요
B14: ='14일'!AH14 -> 0 | I14: =Z8*4910 -> 0 | Q14: =B14+I14 -> 0 | AH14: =Q14-Y15 -> 0
Y15: =Y14*0.75 -> 0
B17: 3.주류제성 및 출고현황
B18: 익일 보쌈 | E18: 보쌈 | I18: 입국 | M18: 1단 | U18: 2단 1일 | Y18: 2단 2일 | AC18: 3일 이상 | AG18: 4일 이상 | AK18: 5일 이상 | AO18: 6일 이상 | AS18: 계
M19: 1일 | Q19: 2일
I20: ='14일'!E20 -> 0 | M20: ='14일'!I20 -> 0 | Q20: ='14일'!Q20+'14일'!M22-'15일'!J8 -> 0 | U20: =J8 -> 0 | Y20: ='14일'!U20 -> 0 | AC20: ='14일'!Y20 -> 0 | AG20: =AY21 -> 0 | AK20: 0 | AO20: 0 | AS20: =AH8 -> 0
AY21: =AH8-U20-Y20-AC20 -> 0
I22: ='14일'!E22 -> 0 | M22: ='14일'!I22 -> 0 | AY22: =AG20 -> 0
B25: 4.원료 및 연료수불상황 | O25: =U20*8 -> 0 | P25: =Y20*3 -> 0 | R25: =AC20*3 -> 0
B26: 구분 | H26: 백미 | N26: 팽화미 | T26: 올리고당 | Z26: 효모 | AF26: 곡자 | AL26: 감미 | AR26: 구연산
B27: 이월수량 | H27: ='14일'!H30:M30 -> 0 | N27: ='14일'!N30:S30 -> 0 | T27: ='14일'!T30:Y30 -> 0 | Z27: ='14일'!Z30:AE30 -> 0 | AF27: ='14일'!AF30:AK30 -> 0 | AL27: ='14일'!AL30:AQ30 -> 0 | AR27: ='14일'!AR30:AW30 -> 0
B28: 당일구입
B29: 당일사용 | H29: =J8*280/40 -> 0 | N29: =SUM(N25:S25) -> 0 | T29: =AC20*72 -> 0 | Z29: =M20*500+Z31 -> 0 | AF29: =J8*4 -> 0 | AL29: =Z8*545 -> 0 | AR29: =Z8*95 -> 0
B30: 잔량 | H30: =H27+H28-H29 -> 0 | N30: =N27+N28-N29 -> 0 | T30: =T27+T28-T29 -> 0 | Z30: =Z27+Z28-Z29-Z31 -> 0 | AF30: =AF27+AF28-AF29 -> 0 | AL30: =AL27+AL28-AL29 -> 0 | AR30: =AR27+AR28-AR29 -> 0
B33: 6. 용기, 마개 | P33: 2
I34: 전일잔량 | P34: 입고 | W34: 출고 | AD34: 파손 | AJ34: 파손재고 | AQ34: 금일재고
B35: 용기 | I35: ='14일'!AQ35 -> 0 | W35: =Y14 -> 0 | AJ35: =AD35+'14일'!AJ35:AP35 -> 0 | AQ35: =I35+P35-W35-AD35 -> 0
B36: 마개 | I36: ='14일'!AQ36 -> 0 | P36: =T33*672000 -> 0 | W36: =W35 -> 0 | AJ36: =AD36+'14일'!AJ36:AP36 -> 0 | AQ36: =I36+P36-W36-AD36 -> 0

Sheet 16일
A1: 서 울 탁 주 강 동 연 합 제 조 장
A3: 현 황 일 보 | AI3: ='5일'!AI3:AW4+11 -> 46128
B5: 1.주료사입현황
B6: 이월수량 | J6: 당일사입수량 | R6: 계 | Z6: 당일제성수량 | AH6: 당일 잔수량 | AP6: 적요
B8: ='15일'!AH8 -> 0 | R8: =B8+J8 -> 0 | AH8: =R8-Z8 -> 0 | AY8: =AH8 -> 0
B11: 2.주류제성 및 출고현황
B12: 이월수량 | I12: 당일제성수량 | Q12: 계 | Y12: 당일판매수량 | AH12: 당일 잔수량 | AP12: 적요
B14: ='15일'!AH14 -> 0 | I14: =Z8*4910 -> 0 | Q14: =B14+I14 -> 0 | AH14: =Q14-Y15 -> 0
Y15: =Y14*0.75 -> 0
B17: 3.주류제성 및 출고현황
B18: 익일 보쌈 | E18: 보쌈 | I18: 입국 | M18: 1단 | U18: 2단 1일 | Y18: 2단 2일 | AC18: 3일 이상 | AG18: 4일 이상 | AK18: 5일 이상 | AO18: 6일 이상 | AS18: 계
M19: 1일 | Q19: 2일
I20: ='15일'!E20 -> 0 | M20: ='15일'!I20 -> 0 | Q20: ='15일'!Q20+'15일'!M22-'16일'!J8 -> 0 | U20: =J8 -> 0 | Y20: ='15일'!U20 -> 0 | AC20: ='15일'!Y20 -> 0 | AG20: =AY21 -> 0 | AK20: 0 | AO20: 0 | AS20: =AH8 -> 0
AY21: =AH8-U20-Y20-AC20 -> 0
I22: ='15일'!E22 -> 0 | M22: ='15일'!I22 -> 0 | AY22: =AG20 -> 0
B25: 4.원료 및 연료수불상황 | O25: =U20*8 -> 0 | P25: =Y20*3 -> 0 | R25: =AC20*3 -> 0
B26: 구분 | H26: 백미 | N26: 팽화미 | T26: 올리고당 | Z26: 효모 | AF26: 곡자 | AL26: 감미 | AR26: 구연산
B27: 이월수량 | H27: ='15일'!H30:M30 -> 0 | N27: ='15일'!N30:S30 -> 0 | T27: ='15일'!T30:Y30 -> 0 | Z27: ='15일'!Z30:AE30 -> 0 | AF27: ='15일'!AF30:AK30 -> 0 | AL27: ='15일'!AL30:AQ30 -> 0 | AR27: ='15일'!AR30:AW30 -> 0
B28: 당일구입
B29: 당일사용 | H29: =J8*280/40 -> 0 | N29: =SUM(N25:S25) -> 0 | T29: =AC20*72 -> 0 | Z29: =M20*500+Z31 -> 0 | AF29: =J8*4 -> 0 | AL29: =Z8*545 -> 0 | AR29: =Z8*95 -> 0
B30: 잔량 | H30: =H27+H28-H29 -> 0 | N30: =N27+N28-N29 -> 0 | T30: =T27+T28-T29 -> 0 | Z30: =Z27+Z28-Z29 -> 0 | AF30: =AF27+AF28-AF29 -> 0 | AL30: =AL27+AL28-AL29 -> 0 | AR30: =AR27+AR28-AR29 -> 0
B33: 6. 용기, 마개 | P33: 0
I34: 전일잔량 | P34: 입고 | W34: 출고 | AD34: 파손 | AJ34: 파손재고 | AQ34: 금일재고
B35: 용기 | I35: ='15일'!AQ35 -> 0 | W35: =Y14 -> 0 | AJ35: =AD35+'15일'!AJ35:AP35 -> 0 | AQ35: =I35+P35-W35-AD35 -> 0
B36: 마개 | I36: ='15일'!AQ36 -> 0 | P36: =T33*672000 -> 0 | W36: =W35 -> 0 | AJ36: =AD36+'15일'!AJ36:AP36 -> 0 | AQ36: =I36+P36-W36-AD36 -> 0

Sheet 17일
A1: 서 울 탁 주 강 동 연 합 제 조 장
A3: 현 황 일 보 | AI3: ='5일'!AI3:AW4+12 -> 46129
B5: 1.주료사입현황
B6: 이월수량 | J6: 당일사입수량 | R6: 계 | Z6: 당일제성수량 | AH6: 당일 잔수량 | AP6: 적요
B8: ='16일'!AH8 -> 0 | R8: =B8+J8 -> 0 | AH8: =R8-Z8 -> 0 | AY8: =AH8 -> 0
B11: 2.주류제성 및 출고현황
B12: 이월수량 | I12: 당일제성수량 | Q12: 계 | Y12: 당일판매수량 | AH12: 당일 잔수량 | AP12: 적요
B14: ='16일'!AH14 -> 0 | I14: =Z8*4910 -> 0 | Q14: =B14+I14 -> 0 | AH14: =Q14-Y15 -> 0
Y15: =Y14*0.75 -> 0
B17: 3.주류제성 및 출고현황
B18: 익일 보쌈 | E18: 보쌈 | I18: 입국 | M18: 1단 | U18: 2단 1일 | Y18: 2단 2일 | AC18: 3일 이상 | AG18: 4일 이상 | AK18: 5일 이상 | AO18: 6일 이상 | AS18: 계
M19: 1일 | Q19: 2일
I20: ='16일'!E20 -> 0 | M20: ='16일'!I20 -> 0 | Q20: ='16일'!Q20+'16일'!M22-'17일'!J8 -> 0 | U20: =J8 -> 0 | Y20: ='16일'!U20 -> 0 | AC20: ='16일'!Y20 -> 0 | AG20: =AY21 -> 0 | AK20: 0 | AO20: 0 | AS20: =AH8 -> 0
AY21: =AH8-U20-Y20-AC20 -> 0
I22: ='16일'!E22 -> 0 | M22: ='16일'!I22 -> 0 | AY22: =AG20 -> 0
B25: 4.원료 및 연료수불상황 | O25: =U20*8 -> 0 | P25: =Y20*3 -> 0 | R25: =AC20*3 -> 0
B26: 구분 | H26: 백미 | N26: 팽화미 | T26: 올리고당 | Z26: 효모 | AF26: 곡자 | AL26: 감미 | AR26: 구연산
B27: 이월수량 | H27: ='16일'!H30:M30 -> 0 | N27: ='16일'!N30:S30 -> 0 | T27: ='16일'!T30:Y30 -> 0 | Z27: ='16일'!Z30:AE30 -> 0 | AF27: ='16일'!AF30:AK30 -> 0 | AL27: ='16일'!AL30:AQ30 -> 0 | AR27: ='16일'!AR30:AW30 -> 0
B28: 당일구입
B29: 당일사용 | H29: =J8*280/40 -> 0 | N29: =SUM(N25:S25) -> 0 | T29: =AC20*72 -> 0 | Z29: =M20*500+Z31 -> 0 | AF29: =J8*4 -> 0 | AL29: =Z8*545 -> 0 | AR29: =Z8*95 -> 0
B30: 잔량 | H30: =H27+H28-H29 -> 0 | N30: =N27+N28-N29 -> 0 | T30: =T27+T28-T29 -> 0 | Z30: =Z27+Z28-Z29 -> 0 | AF30: =AF27+AF28-AF29 -> 0 | AL30: =AL27+AL28-AL29 -> 0 | AR30: =AR27+AR28-AR29 -> 0
B33: 6. 용기, 마개 | P33: 2
I34: 전일잔량 | P34: 입고 | W34: 출고 | AD34: 파손 | AJ34: 파손재고 | AQ34: 금일재고
B35: 용기 | I35: ='16일'!AQ35 -> 0 | W35: =Y14 -> 0 | AJ35: =AD35+'16일'!AJ35:AP35 -> 0 | AQ35: =I35+P35-W35-AD35 -> 0
B36: 마개 | I36: ='16일'!AQ36 -> 0 | P36: =T33*672000 -> 0 | W36: =W35 -> 0 | AJ36: =AD36+'16일'!AJ36:AP36 -> 0 | AQ36: =I36+P36-W36-AD36 -> 0

Sheet 18일
A1: 서 울 탁 주 강 동 연 합 제 조 장
A3: 현 황 일 보 | AI3: ='5일'!AI3:AW4+13 -> 46130
B5: 1.주료사입현황
B6: 이월수량 | J6: 당일사입수량 | R6: 계 | Z6: 당일제성수량 | AH6: 당일 잔수량 | AP6: 적요
B8: ='17일'!AH8 -> 0 | R8: =B8+J8 -> 0 | AH8: =R8-Z8 -> 0 | AY8: =AH8 -> 0
B11: 2.주류제성 및 출고현황
B12: 이월수량 | I12: 당일제성수량 | Q12: 계 | Y12: 당일판매수량 | AH12: 당일 잔수량 | AP12: 적요
B14: ='17일'!AH14 -> 0 | I14: =Z8*4910 -> 0 | Q14: =B14+I14 -> 0 | AH14: =Q14-Y15 -> 0
Y15: =Y14*0.75 -> 0
B17: 3.주류제성 및 출고현황
B18: 익일 보쌈 | E18: 보쌈 | I18: 입국 | M18: 1단 | U18: 2단 1일 | Y18: 2단 2일 | AC18: 3일 이상 | AG18: 4일 이상 | AK18: 5일 이상 | AO18: 6일 이상 | AS18: 계
M19: 1일 | Q19: 2일
I20: ='17일'!E20 -> 0 | M20: ='17일'!I20 -> 0 | Q20: ='17일'!Q20+'17일'!M22-'18일'!J8 -> 0 | U20: =J8 -> 0 | Y20: ='17일'!U20 -> 0 | AC20: ='17일'!Y20 -> 0 | AG20: =AY21 -> 0 | AK20: 0 | AO20: 0 | AS20: =AH8 -> 0
AY21: =AH8-U20-Y20-AC20 -> 0
I22: ='17일'!E22 -> 0 | M22: ='17일'!I22 -> 0 | AY22: =AG20 -> 0
B25: 4.원료 및 연료수불상황 | O25: =U20*8 -> 0 | P25: =Y20*3 -> 0 | R25: =AC20*3 -> 0
B26: 구분 | H26: 백미 | N26: 팽화미 | T26: 올리고당 | Z26: 효모 | AF26: 곡자 | AL26: 감미 | AR26: 구연산
B27: 이월수량 | H27: ='17일'!H30:M30 -> 0 | N27: ='17일'!N30:S30 -> 0 | T27: ='17일'!T30:Y30 -> 0 | Z27: ='17일'!Z30:AE30 -> 0 | AF27: ='17일'!AF30:AK30 -> 0 | AL27: ='17일'!AL30:AQ30 -> 0 | AR27: ='17일'!AR30:AW30 -> 0
B28: 당일구입
B29: 당일사용 | H29: =J8*280/40 -> 0 | N29: =SUM(N25:S25) -> 0 | T29: =AC20*72 -> 0 | Z29: =M20*500+Z31 -> 0 | AF29: =J8*4 -> 0 | AL29: =Z8*545 -> 0 | AR29: =Z8*95 -> 0
B30: 잔량 | H30: =H27+H28-H29 -> 0 | N30: =N27+N28-N29 -> 0 | T30: =T27+T28-T29 -> 0 | Z30: =Z27+Z28-Z29 -> 0 | AF30: =AF27+AF28-AF29 -> 0 | AL30: =AL27+AL28-AL29 -> 0 | AR30: =AR27+AR28-AR29 -> 0
B33: 6. 용기, 마개 | P33: 2
I34: 전일잔량 | P34: 입고 | W34: 출고 | AD34: 파손 | AJ34: 파손재고 | AQ34: 금일재고
B35: 용기 | I35: ='17일'!AQ35 -> 0 | P35: 0 | W35: =Y14 -> 0 | AJ35: =AD35+'17일'!AJ35:AP35 -> 0 | AQ35: =I35+P35-W35-AD35 -> 0
B36: 마개 | I36: ='17일'!AQ36 -> 0 | P36: =T33*672000 -> 0 | W36: =W35 -> 0 | AJ36: =AD36+'17일'!AJ36:AP36 -> 0 | AQ36: =I36+P36-W36-AD36 -> 0

Sheet 19일
A1: 서 울 탁 주 강 동 연 합 제 조 장
A3: 현 황 일 보 | AI3: ='5일'!AI3:AW4+14 -> 46131
B5: 1.주료사입현황
B6: 이월수량 | J6: 당일사입수량 | R6: 계 | Z6: 당일제성수량 | AH6: 당일 잔수량 | AP6: 적요
B8: ='18일'!AH8 -> 0 | R8: =B8+J8 -> 0 | AH8: =R8-Z8 -> 0 | AY8: =AH8 -> 0
B11: 2.주류제성 및 출고현황
B12: 이월수량 | I12: 당일제성수량 | Q12: 계 | Y12: 당일판매수량 | AH12: 당일 잔수량 | AP12: 적요
B14: ='18일'!AH14 -> 0 | I14: =Z8*4910 -> 0 | Q14: =B14+I14 -> 0 | AH14: =Q14-Y15 -> 0
Y15: =Y14*0.75 -> 0
B17: 3.주류제성 및 출고현황
B18: 익일 보쌈 | E18: 보쌈 | I18: 입국 | M18: 1단 | U18: 2단 1일 | Y18: 2단 2일 | AC18: 3일 이상 | AG18: 4일 이상 | AK18: 5일 이상 | AO18: 6일 이상 | AS18: 계
M19: 1일 | Q19: 2일 | AZ19: `
I20: ='18일'!E20 -> 0 | M20: ='18일'!I20 -> 0 | Q20: ='18일'!Q20+'18일'!M22-'19일'!J8 -> 0 | U20: =J8 -> 0 | Y20: ='18일'!U20 -> 0 | AC20: ='18일'!Y20 -> 0 | AG20: =AY21 -> 0 | AK20: 0 | AO20: 0 | AS20: =AH8 -> 0
AY21: =AH8-U20-Y20-AC20 -> 0
I22: ='18일'!E22 -> 0 | M22: ='18일'!I22 -> 0 | AY22: =AG20 -> 0
B25: 4.원료 및 연료수불상황 | O25: =U20*8 -> 0 | P25: =Y20*3 -> 0 | R25: =AC20*3 -> 0
B26: 구분 | H26: 백미 | N26: 팽화미 | T26: 올리고당 | Z26: 효모 | AF26: 곡자 | AL26: 감미 | AR26: 구연산
B27: 이월수량 | H27: ='18일'!H30:M30 -> 0 | N27: ='18일'!N30:S30 -> 0 | T27: ='18일'!T30:Y30 -> 0 | Z27: ='18일'!Z30:AE30 -> 0 | AF27: ='18일'!AF30:AK30 -> 0 | AL27: ='18일'!AL30:AQ30 -> 0 | AR27: ='18일'!AR30:AW30 -> 0
B28: 당일구입
B29: 당일사용 | H29: =J8*280/40 -> 0 | N29: =SUM(N25:S25) -> 0 | T29: =AC20*72 -> 0 | Z29: =M20*500+Z31 -> 0 | AF29: =J8*4 -> 0 | AL29: =Z8*545 -> 0 | AR29: =Z8*95 -> 0
B30: 잔량 | H30: =H27+H28-H29 -> 0 | N30: =N27+N28-N29 -> 0 | T30: =T27+T28-T29 -> 0 | Z30: =Z27+Z28-Z29 -> 0 | AF30: =AF27+AF28-AF29 -> 0 | AL30: =AL27+AL28-AL29 -> 0 | AR30: =AR27+AR28-AR29 -> 0
B33: 6. 용기, 마개 | P33: 2
I34: 전일잔량 | P34: 입고 | W34: 출고 | AD34: 파손 | AJ34: 파손재고 | AQ34: 금일재고
B35: 용기 | I35: ='18일'!AQ35 -> 0 | W35: =Y14 -> 0 | AJ35: =AD35+'18일'!AJ35:AP35 -> 0 | AQ35: =I35+P35-W35-AD35 -> 0
B36: 마개 | I36: ='18일'!AQ36 -> 0 | P36: =T33*672000 -> 0 | W36: =W35 -> 0 | AJ36: =AD36+'18일'!AJ36:AP36 -> 0 | AQ36: =I36+P36-W36-AD36 -> 0
AE38: .

Sheet 20일
A1: 서 울 탁 주 강 동 연 합 제 조 장
A3: 현 황 일 보 | AI3: ='5일'!AI3:AW4+15 -> 46132
B5: 1.주료사입현황
B6: 이월수량 | J6: 당일사입수량 | R6: 계 | Z6: 당일제성수량 | AH6: 당일 잔수량 | AP6: 적요
B8: ='19일'!AH8 -> 0 | R8: =B8+J8 -> 0 | AH8: =R8-Z8 -> 0 | AY8: =AH8 -> 0
B11: 2.주류제성 및 출고현황
B12: 이월수량 | I12: 당일제성수량 | Q12: 계 | Y12: 당일판매수량 | AH12: 당일 잔수량 | AP12: 적요
B14: ='19일'!AH14 -> 0 | I14: =Z8*4910 -> 0 | Q14: =B14+I14 -> 0 | AH14: =Q14-Y15 -> 0
Y15: =Y14*0.75 -> 0
B17: 3.주류제성 및 출고현황
B18: 익일 보쌈 | E18: 보쌈 | I18: 입국 | M18: 1단 | U18: 2단 1일 | Y18: 2단 2일 | AC18: 3일 이상 | AG18: 4일 이상 | AK18: 5일 이상 | AO18: 6일 이상 | AS18: 계
M19: 1일 | Q19: 2일
I20: ='19일'!E20 -> 0 | M20: ='19일'!I20 -> 0 | Q20: ='19일'!Q20+'19일'!M22-'20일'!J8 -> 0 | U20: =J8 -> 0 | Y20: ='19일'!U20 -> 0 | AC20: ='19일'!Y20 -> 0 | AG20: =AY21 -> 0 | AK20: 0 | AO20: 0 | AS20: =AH8 -> 0
AY21: =AH8-U20-Y20-AC20 -> 0
I22: ='19일'!E22 -> 0 | M22: ='19일'!I22 -> 0 | AY22: =AG20 -> 0
B25: 4.원료 및 연료수불상황 | O25: =U20*8 -> 0 | P25: =Y20*3 -> 0 | R25: =AC20*3 -> 0
B26: 구분 | H26: 백미 | N26: 팽화미 | T26: 올리고당 | Z26: 효모 | AF26: 곡자 | AL26: 감미 | AR26: 구연산
B27: 이월수량 | H27: ='19일'!H30:M30 -> 0 | N27: ='19일'!N30:S30 -> 0 | T27: ='19일'!T30:Y30 -> 0 | Z27: ='19일'!Z30:AE30 -> 0 | AF27: ='19일'!AF30:AK30 -> 0 | AL27: ='19일'!AL30:AQ30 -> 0 | AR27: ='19일'!AR30:AW30 -> 0
B28: 당일구입
B29: 당일사용 | H29: =J8*280/40 -> 0 | N29: =SUM(N25:S25) -> 0 | T29: =AC20*72 -> 0 | Z29: =M20*500+Z31 -> 0 | AF29: =J8*4 -> 0 | AL29: =Z8*545 -> 0 | AR29: =Z8*95 -> 0
B30: 잔량 | H30: =H27+H28-H29 -> 0 | N30: =N27+N28-N29 -> 0 | T30: =T27+T28-T29 -> 0 | Z30: =Z27+Z28-Z29 -> 0 | AF30: =AF27+AF28-AF29 -> 0 | AL30: =AL27+AL28-AL29 -> 0 | AR30: =AR27+AR28-AR29 -> 0
B33: 6. 용기, 마개 | P33: 3
I34: 전일잔량 | P34: 입고 | W34: 출고 | AD34: 파손 | AJ34: 파손재고 | AQ34: 금일재고
B35: 용기 | I35: ='19일'!AQ35 -> 0 | W35: =Y14 -> 0 | AJ35: =AD35+'19일'!AJ35:AP35 -> 0 | AQ35: =I35+P35-W35-AD35 -> 0
B36: 마개 | I36: ='19일'!AQ36 -> 0 | P36: =T33*672000 -> 0 | W36: =W35 -> 0 | AJ36: =AD36+'19일'!AJ36:AP36 -> 0 | AQ36: =I36+P36-W36-AD36 -> 0

Sheet 21일
A1: 서 울 탁 주 강 동 연 합 제 조 장
A3: 현 황 일 보 | AI3: ='5일'!AI3:AW4+16 -> 46133
B5: 1.주료사입현황
B6: 이월수량 | J6: 당일사입수량 | R6: 계 | Z6: 당일제성수량 | AH6: 당일 잔수량 | AP6: 적요
B8: ='20일'!AH8 -> 0 | R8: =B8+J8 -> 0 | AH8: =R8-Z8 -> 0 | AY8: =AH8 -> 0
B11: 2.주류제성 및 출고현황
B12: 이월수량 | I12: 당일제성수량 | Q12: 계 | Y12: 당일판매수량 | AH12: 당일 잔수량 | AP12: 적요
B14: ='20일'!AH14 -> 0 | I14: =Z8*4910 -> 0 | Q14: =B14+I14 -> 0 | AH14: =Q14-Y15 -> 0
Y15: =Y14*0.75 -> 0
B17: 3.주류제성 및 출고현황
B18: 익일 보쌈 | E18: 보쌈 | I18: 입국 | M18: 1단 | U18: 2단 1일 | Y18: 2단 2일 | AC18: 3일 이상 | AG18: 4일 이상 | AK18: 5일 이상 | AO18: 6일 이상 | AS18: 계
M19: 1일 | Q19: 2일
I20: ='20일'!E20 -> 0 | M20: ='20일'!I20 -> 0 | Q20: ='20일'!Q20+'20일'!M22-'21일'!J8 -> 0 | U20: =J8 -> 0 | Y20: ='20일'!U20 -> 0 | AC20: ='20일'!Y20 -> 0 | AG20: =AY21 -> 0 | AK20: 0 | AO20: 0 | AS20: =AH8 -> 0
AY21: =AH8-U20-Y20-AC20 -> 0
I22: ='20일'!E22 -> 0 | M22: ='20일'!I22 -> 0 | AY22: =AG20 -> 0
B25: 4.원료 및 연료수불상황 | O25: =U20*8 -> 0 | P25: =Y20*3 -> 0 | R25: =AC20*3 -> 0
B26: 구분 | H26: 백미 | N26: 팽화미 | T26: 올리고당 | Z26: 효모 | AF26: 곡자 | AL26: 감미 | AR26: 구연산
B27: 이월수량 | H27: ='20일'!H30:M30 -> 0 | N27: ='20일'!N30:S30 -> 0 | T27: ='20일'!T30:Y30 -> 0 | Z27: ='20일'!Z30:AE30 -> 0 | AF27: ='20일'!AF30:AK30 -> 0 | AL27: ='20일'!AL30:AQ30 -> 0 | AR27: ='20일'!AR30:AW30 -> 0
B28: 당일구입
B29: 당일사용 | H29: =J8*280/40 -> 0 | N29: =SUM(N25:S25) -> 0 | T29: =AC20*72 -> 0 | Z29: =M20*500+Z31 -> 0 | AF29: =J8*4 -> 0 | AL29: =Z8*545 -> 0 | AR29: =Z8*95 -> 0
B30: 잔량 | H30: =H27+H28-H29 -> 0 | N30: =N27+N28-N29 -> 0 | T30: =T27+T28-T29 -> 0 | Z30: =Z27+Z28-Z29 -> 0 | AF30: =AF27+AF28-AF29 -> 0 | AL30: =AL27+AL28-AL29 -> 0 | AR30: =AR27+AR28-AR29 -> 0
B33: 6. 용기, 마개 | P33: 0
I34: 전일잔량 | P34: 입고 | W34: 출고 | AD34: 파손 | AJ34: 파손재고 | AQ34: 금일재고
B35: 용기 | I35: ='20일'!AQ35 -> 0 | W35: =Y14 -> 0 | AJ35: =AD35+'20일'!AJ35:AP35 -> 0 | AQ35: =I35+P35-W35-AD35 -> 0
B36: 마개 | I36: ='20일'!AQ36 -> 0 | P36: =T33*672000 -> 0 | W36: =W35 -> 0 | AJ36: =AD36+'20일'!AJ36:AP36 -> 0 | AQ36: =I36+P36-W36-AD36 -> 0

Sheet 22일
A1: 서 울 탁 주 강 동 연 합 제 조 장
A3: 현 황 일 보 | AI3: ='5일'!AI3:AW4+17 -> 46134
B5: 1.주료사입현황
B6: 이월수량 | J6: 당일사입수량 | R6: 계 | Z6: 당일제성수량 | AH6: 당일 잔수량 | AP6: 적요
B8: ='21일'!AH8 -> 0 | R8: =B8+J8 -> 0 | AH8: =R8-Z8 -> 0 | AY8: =AH8 -> 0
B11: 2.주류제성 및 출고현황
B12: 이월수량 | I12: 당일제성수량 | Q12: 계 | Y12: 당일판매수량 | AH12: 당일 잔수량 | AP12: 적요
B14: ='21일'!AH14 -> 0 | I14: =Z8*4910 -> 0 | Q14: =B14+I14 -> 0 | AH14: =Q14-Y15 -> 0
Y15: =Y14*0.75 -> 0
B17: 3.주류제성 및 출고현황
B18: 익일 보쌈 | E18: 보쌈 | I18: 입국 | M18: 1단 | U18: 2단 1일 | Y18: 2단 2일 | AC18: 3일 이상 | AG18: 4일 이상 | AK18: 5일 이상 | AO18: 6일 이상 | AS18: 계
M19: 1일 | Q19: 2일
I20: ='21일'!E20 -> 0 | M20: ='21일'!I20 -> 0 | Q20: ='21일'!Q20+'21일'!M22-'22일'!J8 -> 0 | U20: =J8 -> 0 | Y20: ='21일'!U20 -> 0 | AC20: ='21일'!Y20 -> 0 | AG20: =AY21 -> 0 | AK20: 0 | AO20: 0 | AS20: =AH8 -> 0
AY21: =AH8-U20-Y20-AC20 -> 0
I22: ='21일'!E22 -> 0 | M22: ='21일'!I22 -> 0 | AY22: =AG20 -> 0
B25: 4.원료 및 연료수불상황 | O25: =U20*8 -> 0 | P25: =Y20*3 -> 0 | R25: =AC20*3 -> 0
B26: 구분 | H26: 백미 | N26: 팽화미 | T26: 올리고당 | Z26: 효모 | AF26: 곡자 | AL26: 감미 | AR26: 구연산
B27: 이월수량 | H27: ='21일'!H30:M30 -> 0 | N27: ='21일'!N30:S30 -> 0 | T27: ='21일'!T30:Y30 -> 0 | Z27: ='21일'!Z30:AE30 -> 0 | AF27: ='21일'!AF30:AK30 -> 0 | AL27: ='21일'!AL30:AQ30 -> 0 | AR27: ='21일'!AR30:AW30 -> 0
B28: 당일구입
B29: 당일사용 | H29: =J8*280/40 -> 0 | N29: =SUM(N25:S25) -> 0 | T29: =AC20*72 -> 0 | Z29: =M20*500+Z31 -> 0 | AF29: =J8*4 -> 0 | AL29: =Z8*545 -> 0 | AR29: =Z8*95 -> 0
B30: 잔량 | H30: =H27+H28-H29 -> 0 | N30: =N27+N28-N29 -> 0 | T30: =T27+T28-T29 -> 0 | Z30: =Z27+Z28-Z29 -> 0 | AF30: =AF27+AF28-AF29 -> 0 | AL30: =AL27+AL28-AL29 -> 0 | AR30: =AR27+AR28-AR29 -> 0
B33: 6. 용기, 마개 | P33: 2
I34: 전일잔량 | P34: 입고 | W34: 출고 | AD34: 파손 | AJ34: 파손재고 | AQ34: 금일재고
B35: 용기 | I35: ='21일'!AQ35 -> 0 | W35: =Y14 -> 0 | AJ35: =AD35+'21일'!AJ35:AP35 -> 0 | AQ35: =I35+P35-W35-AD35 -> 0
B36: 마개 | I36: ='21일'!AQ36 -> 0 | P36: =T33*672000 -> 0 | W36: =W35 -> 0 | AJ36: =AD36+'21일'!AJ36:AP36 -> 0 | AQ36: =I36+P36-W36-AD36 -> 0

Sheet 23일
A1: 서 울 탁 주 강 동 연 합 제 조 장
A3: 현 황 일 보 | AI3: ='5일'!AI3:AW4+18 -> 46135
B5: 1.주료사입현황
B6: 이월수량 | J6: 당일사입수량 | R6: 계 | Z6: 당일제성수량 | AH6: 당일 잔수량 | AP6: 적요
B8: ='22일'!AH8 -> 0 | R8: =B8+J8 -> 0 | AH8: =R8-Z8 -> 0 | AY8: =AH8 -> 0
B11: 2.주류제성 및 출고현황
B12: 이월수량 | I12: 당일제성수량 | Q12: 계 | Y12: 당일판매수량 | AH12: 당일 잔수량 | AP12: 적요
B14: ='22일'!AH14 -> 0 | I14: =Z8*4910 -> 0 | Q14: =B14+I14 -> 0 | AH14: =Q14-Y15 -> 0
Y15: =Y14*0.75 -> 0
B17: 3.주류제성 및 출고현황
B18: 익일 보쌈 | E18: 보쌈 | I18: 입국 | M18: 1단 | U18: 2단 1일 | Y18: 2단 2일 | AC18: 3일 이상 | AG18: 4일 이상 | AK18: 5일 이상 | AO18: 6일 이상 | AS18: 계
M19: 1일 | Q19: 2일
I20: ='22일'!E20 -> 0 | M20: ='22일'!I20 -> 0 | Q20: ='22일'!Q20+'22일'!M22-'23일'!J8 -> 0 | U20: =J8 -> 0 | Y20: ='22일'!U20 -> 0 | AC20: ='22일'!Y20 -> 0 | AG20: =AY21 -> 0 | AK20: 0 | AO20: 0 | AS20: =AH8 -> 0
AY21: =AH8-U20-Y20-AC20 -> 0
I22: ='22일'!E22 -> 0 | M22: ='22일'!I22 -> 0 | AY22: =AG20 -> 0
B25: 4.원료 및 연료수불상황 | O25: =U20*8 -> 0 | P25: =Y20*3 -> 0 | R25: =AC20*3 -> 0
B26: 구분 | H26: 백미 | N26: 팽화미 | T26: 올리고당 | Z26: 효모 | AF26: 곡자 | AL26: 감미 | AR26: 구연산
B27: 이월수량 | H27: ='22일'!H30:M30 -> 0 | N27: ='22일'!N30:S30 -> 0 | T27: ='22일'!T30:Y30 -> 0 | Z27: ='22일'!Z30:AE30 -> 0 | AF27: ='22일'!AF30:AK30 -> 0 | AL27: ='22일'!AL30:AQ30 -> 0 | AR27: ='22일'!AR30:AW30 -> 0
B28: 당일구입
B29: 당일사용 | H29: =J8*280/40 -> 0 | N29: =SUM(N25:S25) -> 0 | T29: =AC20*72 -> 0 | Z29: =M20*500+Z31 -> 0 | AF29: =J8*4 -> 0 | AL29: =Z8*545 -> 0 | AR29: =Z8*95 -> 0
B30: 잔량 | H30: =H27+H28-H29 -> 0 | N30: =N27+N28-N29 -> 0 | T30: =T27+T28-T29 -> 0 | Z30: =Z27+Z28-Z29 -> 0 | AF30: =AF27+AF28-AF29 -> 0 | AL30: =AL27+AL28-AL29 -> 0 | AR30: =AR27+AR28-AR29 -> 0
B33: 6. 용기, 마개 | P33: 2 | T33: 1
I34: 전일잔량 | P34: 입고 | W34: 출고 | AD34: 파손 | AJ34: 파손재고 | AQ34: 금일재고
B35: 용기 | I35: ='22일'!AQ35 -> 0 | W35: =Y14 -> 0 | AJ35: =AD35+'22일'!AJ35:AP35 -> 0 | AQ35: =I35+P35-W35-AD35 -> 0
B36: 마개 | I36: ='22일'!AQ36 -> 0 | W36: =W35 -> 0 | AJ36: =AD36+'22일'!AJ36:AP36 -> 0 | AQ36: =I36+P36-W36-AD36 -> 0

Sheet 24일
A1: 서 울 탁 주 강 동 연 합 제 조 장
A3: 현 황 일 보 | AI3: ='5일'!AI3:AW4+19 -> 46136
B5: 1.주료사입현황
B6: 이월수량 | J6: 당일사입수량 | R6: 계 | Z6: 당일제성수량 | AH6: 당일 잔수량 | AP6: 적요
B8: ='23일'!AH8 -> 0 | R8: =B8+J8 -> 0 | AH8: =R8-Z8 -> 0 | AY8: =AH8 -> 0
B11: 2.주류제성 및 출고현황
B12: 이월수량 | I12: 당일제성수량 | Q12: 계 | Y12: 당일판매수량 | AH12: 당일 잔수량 | AP12: 적요
B14: ='23일'!AH14 -> 0 | I14: =Z8*4910 -> 0 | Q14: =B14+I14 -> 0 | AH14: =Q14-Y15 -> 0
Y15: =Y14*0.75 -> 0
B17: 3.주류제성 및 출고현황
B18: 익일 보쌈 | E18: 보쌈 | I18: 입국 | M18: 1단 | U18: 2단 1일 | Y18: 2단 2일 | AC18: 3일 이상 | AG18: 4일 이상 | AK18: 5일 이상 | AO18: 6일 이상 | AS18: 계
M19: 1일 | Q19: 2일
I20: ='23일'!E20 -> 0 | M20: ='23일'!I20 -> 0 | Q20: ='23일'!Q20+'23일'!M22-'24일'!J8 -> 0 | U20: =J8 -> 0 | Y20: ='23일'!U20 -> 0 | AC20: ='23일'!Y20 -> 0 | AG20: =AY21 -> 0 | AK20: 0 | AO20: 0 | AS20: =AH8 -> 0
AY21: =AH8-U20-Y20-AC20 -> 0
I22: ='23일'!E22 -> 0 | M22: ='23일'!I22 -> 0 | AY22: =AG20 -> 0
B25: 4.원료 및 연료수불상황 | O25: =U20*8 -> 0 | P25: =Y20*3 -> 0 | R25: =AC20*3 -> 0
B26: 구분 | H26: 백미 | N26: 팽화미 | T26: 올리고당 | Z26: 효모 | AF26: 곡자 | AL26: 감미 | AR26: 구연산
B27: 이월수량 | H27: ='23일'!H30:M30 -> 0 | N27: ='23일'!N30:S30 -> 0 | T27: ='23일'!T30:Y30 -> 0 | Z27: ='23일'!Z30:AE30 -> 0 | AF27: ='23일'!AF30:AK30 -> 0 | AL27: ='23일'!AL30:AQ30 -> 0 | AR27: ='23일'!AR30:AW30 -> 0
B28: 당일구입
B29: 당일사용 | H29: =J8*280/40 -> 0 | N29: =SUM(N25:S25) -> 0 | T29: =AC20*72 -> 0 | Z29: =M20*500+Z31 -> 0 | AF29: =J8*4 -> 0 | AL29: =Z8*545 -> 0 | AR29: =Z8*95 -> 0
B30: 잔량 | H30: =H27+H28-H29 -> 0 | N30: =N27+N28-N29 -> 0 | T30: =T27+T28-T29 -> 0 | Z30: =Z27+Z28-Z29 -> 0 | AF30: =AF27+AF28-AF29 -> 0 | AL30: =AL27+AL28-AL29 -> 0 | AR30: =AR27+AR28-AR29 -> 0
B33: 6. 용기, 마개 | P33: 0
I34: 전일잔량 | P34: 입고 | W34: 출고 | AD34: 파손 | AJ34: 파손재고 | AQ34: 금일재고
B35: 용기 | I35: ='23일'!AQ35 -> 0 | W35: =Y14 -> 0 | AJ35: =AD35+'23일'!AJ35:AP35 -> 0 | AQ35: =I35+P35-W35-AD35 -> 0
B36: 마개 | I36: ='23일'!AQ36 -> 0 | P36: =T33*672000 -> 0 | W36: =W35 -> 0 | AJ36: =AD36+'23일'!AJ36:AP36 -> 0 | AQ36: =I36+P36-W36-AD36 -> 0

Sheet 25일
A1: 서 울 탁 주 강 동 연 합 제 조 장
A3: 현 황 일 보 | AI3: ='5일'!AI3:AW4+20 -> 46137
B5: 1.주료사입현황
B6: 이월수량 | J6: 당일사입수량 | R6: 계 | Z6: 당일제성수량 | AH6: 당일 잔수량 | AP6: 적요
B8: ='24일'!AH8 -> 0 | R8: =B8+J8 -> 0 | AH8: =R8-Z8 -> 0 | AY8: =AH8 -> 0
B11: 2.주류제성 및 출고현황
B12: 이월수량 | I12: 당일제성수량 | Q12: 계 | Y12: 당일판매수량 | AH12: 당일 잔수량 | AP12: 적요
B14: ='24일'!AH14 -> 0 | I14: =Z8*4910 -> 0 | Q14: =B14+I14 -> 0 | AH14: =Q14-Y15 -> 0
Y15: =Y14*0.75 -> 0
B17: 3.주류제성 및 출고현황
B18: 익일 보쌈 | E18: 보쌈 | I18: 입국 | M18: 1단 | U18: 2단 1일 | Y18: 2단 2일 | AC18: 3일 이상 | AG18: 4일 이상 | AK18: 5일 이상 | AO18: 6일 이상 | AS18: 계
M19: 1일 | Q19: 2일
I20: ='24일'!E20 -> 0 | M20: ='24일'!I20 -> 0 | Q20: ='24일'!Q20+'24일'!M22-'25일'!J8 -> 0 | U20: =J8 -> 0 | Y20: ='24일'!U20 -> 0 | AC20: ='24일'!Y20 -> 0 | AG20: =AY21 -> 0 | AK20: 0 | AO20: 0 | AS20: =AH8 -> 0
AY21: =AH8-U20-Y20-AC20 -> 0
I22: ='24일'!E22 -> 0 | M22: ='24일'!I22 -> 0 | AY22: =AG20 -> 0
B25: 4.원료 및 연료수불상황 | O25: =U20*8 -> 0 | P25: =Y20*3 -> 0 | R25: =AC20*3 -> 0
B26: 구분 | H26: 백미 | N26: 팽화미 | T26: 올리고당 | Z26: 효모 | AF26: 곡자 | AL26: 감미 | AR26: 구연산
B27: 이월수량 | H27: ='24일'!H30:M30 -> 0 | N27: ='24일'!N30:S30 -> 0 | T27: ='24일'!T30:Y30 -> 0 | Z27: ='24일'!Z30:AE30 -> 0 | AF27: ='24일'!AF30:AK30 -> 0 | AL27: ='24일'!AL30:AQ30 -> 0 | AR27: ='24일'!AR30:AW30 -> 0
B28: 당일구입
B29: 당일사용 | H29: =J8*280/40 -> 0 | N29: =SUM(N25:S25) -> 0 | T29: =AC20*72 -> 0 | Z29: =M20*500+Z31 -> 0 | AF29: =J8*4 -> 0 | AL29: =Z8*545 -> 0 | AR29: =Z8*95 -> 0
B30: 잔량 | H30: =H27+H28-H29 -> 0 | N30: =N27+N28-N29 -> 0 | T30: =T27+T28-T29 -> 0 | Z30: =Z27+Z28-Z29 -> 0 | AF30: =AF27+AF28-AF29 -> 0 | AL30: =AL27+AL28-AL29 -> 0 | AR30: =AR27+AR28-AR29 -> 0
B33: 6. 용기, 마개 | P33: 0
I34: 전일잔량 | P34: 입고 | W34: 출고 | AD34: 파손 | AJ34: 파손재고 | AQ34: 금일재고
B35: 용기 | I35: ='24일'!AQ35 -> 0 | W35: =Y14 -> 0 | AJ35: =AD35+'24일'!AJ35:AP35 -> 0 | AQ35: =I35+P35-W35-AD35 -> 0
B36: 마개 | I36: ='24일'!AQ36 -> 0 | P36: =T33*672000 -> 0 | W36: =W35 -> 0 | AJ36: =AD36+'24일'!AJ36:AP36 -> 0 | AQ36: =I36+P36-W36-AD36 -> 0

Sheet 26일
A1: 서 울 탁 주 강 동 연 합 제 조 장
A3: 현 황 일 보 | AI3: ='5일'!AI3:AW4+21 -> 46138
B5: 1.주료사입현황
B6: 이월수량 | J6: 당일사입수량 | R6: 계 | Z6: 당일제성수량 | AH6: 당일 잔수량 | AP6: 적요
B8: ='25일'!AH8 -> 0 | R8: =B8+J8 -> 0 | AH8: =R8-Z8 -> 0 | AY8: =AH8 -> 0
B11: 2.주류제성 및 출고현황
B12: 이월수량 | I12: 당일제성수량 | Q12: 계 | Y12: 당일판매수량 | AH12: 당일 잔수량 | AP12: 적요
B14: ='25일'!AH14 -> 0 | I14: =Z8*4910 -> 0 | Q14: =B14+I14 -> 0 | AH14: =Q14-Y15 -> 0
Y15: =Y14*0.75 -> 0
B17: 3.주류제성 및 출고현황
B18: 익일 보쌈 | E18: 보쌈 | I18: 입국 | M18: 1단 | U18: 2단 1일 | Y18: 2단 2일 | AC18: 3일 이상 | AG18: 4일 이상 | AK18: 5일 이상 | AO18: 6일 이상 | AS18: 계
M19: 1일 | Q19: 2일
I20: ='25일'!E20 -> 0 | M20: ='25일'!I20 -> 0 | Q20: ='25일'!Q20+'25일'!M22-'26일'!J8 -> 0 | U20: =J8 -> 0 | Y20: ='25일'!U20 -> 0 | AC20: ='25일'!Y20 -> 0 | AG20: =AY21 -> 0 | AK20: 0 | AO20: 0 | AS20: =AH8 -> 0
AY21: =AH8-U20-Y20-AC20 -> 0
I22: ='25일'!E22 -> 0 | M22: ='25일'!I22 -> 0 | AY22: =AG20 -> 0
B25: 4.원료 및 연료수불상황 | O25: =U20*8 -> 0 | P25: =Y20*3 -> 0 | R25: =AC20*3 -> 0
B26: 구분 | H26: 백미 | N26: 팽화미 | T26: 올리고당 | Z26: 효모 | AF26: 곡자 | AL26: 감미 | AR26: 구연산
B27: 이월수량 | H27: ='25일'!H30:M30 -> 0 | N27: ='25일'!N30:S30 -> 0 | T27: ='25일'!T30:Y30 -> 0 | Z27: ='25일'!Z30:AE30 -> 0 | AF27: ='25일'!AF30:AK30 -> 0 | AL27: ='25일'!AL30:AQ30 -> 0 | AR27: ='25일'!AR30:AW30 -> 0
B28: 당일구입
B29: 당일사용 | H29: =J8*280/40 -> 0 | N29: =SUM(N25:S25) -> 0 | T29: =AC20*72 -> 0 | Z29: =M20*500+Z31 -> 0 | AF29: =J8*4 -> 0 | AL29: =Z8*545 -> 0 | AR29: =Z8*95 -> 0
B30: 잔량 | H30: =H27+H28-H29 -> 0 | N30: =N27+N28-N29 -> 0 | T30: =T27+T28-T29 -> 0 | Z30: =Z27+Z28-Z29 -> 0 | AF30: =AF27+AF28-AF29 -> 0 | AL30: =AL27+AL28-AL29 -> 0 | AR30: =AR27+AR28-AR29 -> 0
B33: 6. 용기, 마개 | P33: 2
I34: 전일잔량 | P34: 입고 | W34: 출고 | AD34: 파손 | AJ34: 파손재고 | AQ34: 금일재고
B35: 용기 | I35: ='25일'!AQ35 -> 0 | W35: =Y14 -> 0 | AJ35: =AD35+'25일'!AJ35:AP35 -> 0 | AQ35: =I35+P35-W35-AD35 -> 0
B36: 마개 | I36: ='25일'!AQ36 -> 0 | P36: =T33*672000 -> 0 | W36: =W35 -> 0 | AJ36: =AD36+'25일'!AJ36:AP36 -> 0 | AQ36: =I36+P36-W36-AD36 -> 0

Sheet 27일
A1: 서 울 탁 주 강 동 연 합 제 조 장
A3: 현 황 일 보 | AI3: ='5일'!AI3:AW4+22 -> 46139
B5: 1.주료사입현황
B6: 이월수량 | J6: 당일사입수량 | R6: 계 | Z6: 당일제성수량 | AH6: 당일 잔수량 | AP6: 적요
B8: ='26일'!AH8 -> 0 | R8: =B8+J8 -> 0 | AH8: =R8-Z8 -> 0 | AY8: =AH8 -> 0
B11: 2.주류제성 및 출고현황
B12: 이월수량 | I12: 당일제성수량 | Q12: 계 | Y12: 당일판매수량 | AH12: 당일 잔수량 | AP12: 적요
B14: ='26일'!AH14 -> 0 | I14: =Z8*4910 -> 0 | Q14: =B14+I14 -> 0 | AH14: =Q14-Y15 -> 0
Y15: =Y14*0.75 -> 0
B17: 3.주류제성 및 출고현황
B18: 익일 보쌈 | E18: 보쌈 | I18: 입국 | M18: 1단 | U18: 2단 1일 | Y18: 2단 2일 | AC18: 3일 이상 | AG18: 4일 이상 | AK18: 5일 이상 | AO18: 6일 이상 | AS18: 계
M19: 1일 | Q19: 2일
I20: ='26일'!E20 -> 0 | M20: ='26일'!I20 -> 0 | Q20: ='26일'!Q20+'26일'!M22-'27일'!J8 -> 0 | U20: =J8 -> 0 | Y20: ='26일'!U20 -> 0 | AC20: ='26일'!Y20 -> 0 | AG20: =AY21 -> 0 | AK20: 0 | AO20: 0 | AS20: =AH8 -> 0
AY21: =AH8-U20-Y20-AC20 -> 0
I22: ='26일'!E22 -> 0 | M22: ='26일'!I22 -> 0 | AY22: =AG20 -> 0
B25: 4.원료 및 연료수불상황 | O25: =U20*8 -> 0 | P25: =Y20*3 -> 0 | R25: =AC20*3 -> 0
B26: 구분 | H26: 백미 | N26: 팽화미 | T26: 올리고당 | Z26: 효모 | AF26: 곡자 | AL26: 감미 | AR26: 구연산
B27: 이월수량 | H27: ='26일'!H30:M30 -> 0 | N27: ='26일'!N30:S30 -> 0 | T27: ='26일'!T30:Y30 -> 0 | Z27: ='26일'!Z30:AE30 -> 0 | AF27: ='26일'!AF30:AK30 -> 0 | AL27: ='26일'!AL30:AQ30 -> 0 | AR27: ='26일'!AR30:AW30 -> 0
B28: 당일구입
B29: 당일사용 | H29: =J8*280/40 -> 0 | N29: =SUM(N25:S25) -> 0 | T29: =AC20*72 -> 0 | Z29: =M20*500+Z31 -> 0 | AF29: =J8*4 -> 0 | AL29: =Z8*545 -> 0 | AR29: =Z8*95 -> 0
B30: 잔량 | H30: =H27+H28-H29 -> 0 | N30: =N27+N28-N29 -> 0 | T30: =T27+T28-T29 -> 0 | Z30: =Z27+Z28-Z29 -> 0 | AF30: =AF27+AF28-AF29 -> 0 | AL30: =AL27+AL28-AL29 -> 0 | AR30: =AR27+AR28-AR29 -> 0
B33: 6. 용기, 마개 | P33: 3
I34: 전일잔량 | P34: 입고 | W34: 출고 | AD34: 파손 | AJ34: 파손재고 | AQ34: 금일재고
B35: 용기 | I35: ='26일'!AQ35 -> 0 | W35: =Y14 -> 0 | AJ35: =AD35+'26일'!AJ35:AP35 -> 0 | AQ35: =I35+P35-W35-AD35 -> 0
B36: 마개 | I36: ='26일'!AQ36 -> 0 | P36: =T33*672000 -> 0 | W36: =W35 -> 0 | AJ36: =AD36+'26일'!AJ36:AP36 -> 0 | AQ36: =I36+P36-W36-AD36 -> 0

Sheet 28일
A1: 서 울 탁 주 강 동 연 합 제 조 장
A3: 현 황 일 보 | AI3: ='5일'!AI3:AW4+23 -> 46140
B5: 1.주료사입현황
B6: 이월수량 | J6: 당일사입수량 | R6: 계 | Z6: 당일제성수량 | AH6: 당일 잔수량 | AP6: 적요
B8: ='27일'!AH8 -> 0 | R8: =B8+J8 -> 0 | AH8: =R8-Z8 -> 0 | AY8: =AH8 -> 0
B11: 2.주류제성 및 출고현황
B12: 이월수량 | I12: 당일제성수량 | Q12: 계 | Y12: 당일판매수량 | AH12: 당일 잔수량 | AP12: 적요
B14: ='27일'!AH14 -> 0 | I14: =Z8*4910 -> 0 | Q14: =B14+I14 -> 0 | AH14: =Q14-Y15 -> 0
Y15: =Y14*0.75 -> 0
B17: 3.주류제성 및 출고현황
B18: 익일 보쌈 | E18: 보쌈 | I18: 입국 | M18: 1단 | U18: 2단 1일 | Y18: 2단 2일 | AC18: 3일 이상 | AG18: 4일 이상 | AK18: 5일 이상 | AO18: 6일 이상 | AS18: 계
M19: 1일 | Q19: 2일
I20: ='27일'!E20 -> 0 | M20: ='27일'!I20 -> 0 | Q20: ='27일'!Q20+'27일'!M22-'28일'!J8 -> 0 | U20: =J8 -> 0 | Y20: ='27일'!U20 -> 0 | AC20: ='27일'!Y20 -> 0 | AG20: =AY21 -> 0 | AK20: 0 | AO20: 0 | AS20: =AH8 -> 0
AY21: =AH8-U20-Y20-AC20 -> 0
I22: ='27일'!E22 -> 0 | M22: ='27일'!I22 -> 0 | AY22: =AG20 -> 0
B25: 4.원료 및 연료수불상황 | O25: =U20*8 -> 0 | P25: =Y20*3 -> 0 | R25: =AC20*3 -> 0
B26: 구분 | H26: 백미 | N26: 팽화미 | T26: 올리고당 | Z26: 효모 | AF26: 곡자 | AL26: 감미 | AR26: 구연산
B27: 이월수량 | H27: ='27일'!H30:M30 -> 0 | N27: ='27일'!N30:S30 -> 0 | T27: ='27일'!T30:Y30 -> 0 | Z27: ='27일'!Z30:AE30 -> 0 | AF27: ='27일'!AF30:AK30 -> 0 | AL27: ='27일'!AL30:AQ30 -> 0 | AR27: ='27일'!AR30:AW30 -> 0
B28: 당일구입
B29: 당일사용 | H29: =J8*280/40 -> 0 | N29: =SUM(N25:S25) -> 0 | T29: =AC20*72 -> 0 | Z29: =M20*500+Z31 -> 0 | AF29: =J8*4 -> 0 | AL29: =Z8*545 -> 0 | AR29: =Z8*95 -> 0
B30: 잔량 | H30: =H27+H28-H29 -> 0 | N30: =N27+N28-N29 -> 0 | T30: =T27+T28-T29 -> 0 | Z30: =Z27+Z28-Z29 -> 0 | AF30: =AF27+AF28-AF29 -> 0 | AL30: =AL27+AL28-AL29 -> 0 | AR30: =AR27+AR28-AR29 -> 0
B33: 6. 용기, 마개 | P33: 0
I34: 전일잔량 | P34: 입고 | W34: 출고 | AD34: 파손 | AJ34: 파손재고 | AQ34: 금일재고
B35: 용기 | I35: ='27일'!AQ35 -> 0 | W35: =Y14 -> 0 | AJ35: =AD35+'27일'!AJ35:AP35 -> 0 | AQ35: =I35+P35-W35-AD35 -> 0
B36: 마개 | I36: ='27일'!AQ36 -> 0 | P36: =T33*672000 -> 0 | W36: =W35 -> 0 | AJ36: =AD36+'27일'!AJ36:AP36 -> 0 | AQ36: =I36+P36-W36-AD36 -> 0

Sheet 29일
A1: 서 울 탁 주 강 동 연 합 제 조 장
A3: 현 황 일 보 | AI3: ='5일'!AI3:AW4+24 -> 46141
B5: 1.주료사입현황
B6: 이월수량 | J6: 당일사입수량 | R6: 계 | Z6: 당일제성수량 | AH6: 당일 잔수량 | AP6: 적요
B8: ='28일'!AH8 -> 0 | R8: =B8+J8 -> 0 | AH8: =R8-Z8 -> 0 | AY8: =AH8 -> 0
B11: 2.주류제성 및 출고현황
B12: 이월수량 | I12: 당일제성수량 | Q12: 계 | Y12: 당일판매수량 | AH12: 당일 잔수량 | AP12: 적요
B14: ='28일'!AH14 -> 0 | I14: =Z8*4910 -> 0 | Q14: =B14+I14 -> 0 | AH14: =Q14-Y15 -> 0
Y15: =Y14*0.75 -> 0
B17: 3.주류제성 및 출고현황
B18: 익일 보쌈 | E18: 보쌈 | I18: 입국 | M18: 1단 | U18: 2단 1일 | Y18: 2단 2일 | AC18: 3일 이상 | AG18: 4일 이상 | AK18: 5일 이상 | AO18: 6일 이상 | AS18: 계
M19: 1일 | Q19: 2일
I20: ='28일'!E20 -> 0 | M20: ='28일'!I20 -> 0 | Q20: ='28일'!Q20+'28일'!M22-'29일'!J8 -> 0 | U20: =J8 -> 0 | Y20: ='28일'!U20 -> 0 | AC20: ='28일'!Y20 -> 0 | AG20: =AS20-U20-Y20-AC20 -> 0 | AK20: 0 | AO20: 0 | AS20: =AH8 -> 0
AY21: =AH8-U20-Y20-AC20 -> 0
I22: ='28일'!E22 -> 0 | M22: ='28일'!I22 -> 0 | AY22: =AG20 -> 0
B25: 4.원료 및 연료수불상황 | O25: =U20*8 -> 0 | P25: =Y20*3 -> 0 | R25: =AC20*3 -> 0
B26: 구분 | H26: 백미 | N26: 팽화미 | T26: 올리고당 | Z26: 효모 | AF26: 곡자 | AL26: 감미 | AR26: 구연산
B27: 이월수량 | H27: ='28일'!H30:M30 -> 0 | N27: ='28일'!N30:S30 -> 0 | T27: ='28일'!T30:Y30 -> 0 | Z27: ='28일'!Z30:AE30 -> 0 | AF27: ='28일'!AF30:AK30 -> 0 | AL27: ='28일'!AL30:AQ30 -> 0 | AR27: ='28일'!AR30:AW30 -> 0
B28: 당일구입
B29: 당일사용 | H29: =J8*280/40 -> 0 | N29: =SUM(N25:S25) -> 0 | T29: =AC20*72 -> 0 | Z29: =M20*500+Z31 -> 0 | AF29: =J8*4 -> 0 | AL29: =Z8*545 -> 0 | AR29: =Z8*95 -> 0
B30: 잔량 | H30: =H27+H28-H29 -> 0 | N30: =N27+N28-N29 -> 0 | T30: =T27+T28-T29 -> 0 | Z30: =Z27+Z28-Z29 -> 0 | AF30: =AF27+AF28-AF29 -> 0 | AL30: =AL27+AL28-AL29 -> 0 | AR30: =AR27+AR28-AR29 -> 0
B33: 6. 용기, 마개 | P33: 2
I34: 전일잔량 | P34: 입고 | W34: 출고 | AD34: 파손 | AJ34: 파손재고 | AQ34: 금일재고
B35: 용기 | I35: ='28일'!AQ35 -> 0 | W35: =Y14 -> 0 | AJ35: =AD35+'28일'!AJ35:AP35 -> 0 | AQ35: =I35+P35-W35-AD35 -> 0
B36: 마개 | I36: ='28일'!AQ36 -> 0 | P36: =T33*672000 -> 0 | W36: =W35 -> 0 | AJ36: =AD36+'28일'!AJ36:AP36 -> 0 | AQ36: =I36+P36-W36-AD36 -> 0

Sheet 30일
A1: 서 울 탁 주 강 동 연 합 제 조 장
A3: 현 황 일 보 | AI3: ='5일'!AI3:AW4+25 -> 46142
B5: 1.주료사입현황
B6: 이월수량 | J6: 당일사입수량 | R6: 계 | Z6: 당일제성수량 | AH6: 당일 잔수량 | AP6: 적요
B8: ='29일'!AH8 -> 0 | R8: =B8+J8 -> 0 | AH8: =R8-Z8 -> 0 | AY8: =AH8 -> 0
B11: 2.주류제성 및 출고현황
B12: 이월수량 | I12: 당일제성수량 | Q12: 계 | Y12: 당일판매수량 | AH12: 당일 잔수량 | AP12: 적요
B14: ='29일'!AH14 -> 0 | I14: =Z8*4910 -> 0 | Q14: =B14+I14 -> 0 | AH14: =Q14-Y15 -> 0
Y15: =Y14*0.75 -> 0
B17: 3.주류제성 및 출고현황
B18: 익일 보쌈 | E18: 보쌈 | I18: 입국 | M18: 1단 | U18: 2단 1일 | Y18: 2단 2일 | AC18: 3일 이상 | AG18: 4일 이상 | AK18: 5일 이상 | AO18: 6일 이상 | AS18: 계
M19: 1일 | Q19: 2일
I20: ='29일'!E20 -> 0 | M20: ='29일'!I20 -> 0 | Q20: ='29일'!Q20+'29일'!M22-'30일'!J8 -> 0 | U20: =J8 -> 0 | Y20: ='29일'!U20 -> 0 | AC20: ='29일'!Y20 -> 0 | AG20: =AS20-U20-Y20-AC20 -> 0 | AK20: 0 | AO20: 0 | AS20: =AH8 -> 0
AY21: =AH8-U20-Y20-AC20 -> 0
I22: ='29일'!E22 -> 0 | M22: ='29일'!I22 -> 0 | AY22: =AG20 -> 0
B25: 4.원료 및 연료수불상황 | O25: =U20*8 -> 0 | P25: =Y20*3 -> 0 | R25: =AC20*3 -> 0
B26: 구분 | H26: 백미 | N26: 팽화미 | T26: 올리고당 | Z26: 효모 | AF26: 곡자 | AL26: 감미 | AR26: 구연산
B27: 이월수량 | H27: ='29일'!H30:M30 -> 0 | N27: ='29일'!N30:S30 -> 0 | T27: ='29일'!T30:Y30 -> 0 | Z27: ='29일'!Z30:AE30 -> 0 | AF27: ='29일'!AF30:AK30 -> 0 | AL27: ='29일'!AL30:AQ30 -> 0 | AR27: ='29일'!AR30:AW30 -> 0
B28: 당일구입
B29: 당일사용 | H29: =J8*280/40 -> 0 | N29: =SUM(N25:S25) -> 0 | T29: =AC20*72 -> 0 | Z29: =M20*500+Z31 -> 0 | AF29: =J8*4 -> 0 | AL29: =Z8*545 -> 0 | AR29: =Z8*95 -> 0
